Workbook
Name \a: #N/A
Name \d: #REF!
Name \I: #REF!
Name \jy: #REF!
Name \P: #REF!
Name \r: #REF!
Name \x: #N/A
Name \xjy: #REF!
Name \z: #N/A
Name _1_24_method_test: #REF!
Name _1C_: #REF!
Name _801192.SI: "'=OFFSET(动态图标!$+Sheet1!$C$16,1,,COUNT(动态图标!$C:$C))"""
Name _a: #N/A
Name _aaa1: #N/A
Name _C: #REF!
Name _d: #N/A
Name _jgc10: OFFSET(#REF!,0,1*(#REF!-1),COUNTA(#REF!),1)
Name _JX4: #REF!
Name _pb300: OFFSET(#REF!,0,0,COUNTA(#REF!),1)
Name _pe300: OFFSET(#REF!,0,0,COUNTA(#REF!),1)
Name _r: #N/A
Name _sum2: #REF!
Name _TEM1: #REF!
Name _TEM2: #REF!
Name _x: #N/A
Name _Z: #REF!
Name A: #REF!
Name aa: #REF!
Name AAA: #REF!
Name abc: #REF!
Name Add__Cash: #REF!
Name Add__Listed_Investments: #REF!
Name Add__Other_Investments: #REF!
Name All_Institutions: #REF!
Name ALLM: #REF!
Name ALPHABETA: #REF!
Name Asset_Beta: #REF!
Name Asset_classes: #REF!
Name Asset_Concentrations: #REF!
Name Average_premium_rates: #REF!
Name A股加权市净率: #REF!
Name A股加权市盈率: #REF!
Name A股与H股加权溢价: #REF!
Name B: #N/A
Name Balance_sheet: #REF!
Name Balance_sheet_history: #REF!
Name Bank_industry: #REF!
Name bb: #REF!
Name bd_title: #REF!
Name BETA: #REF!
Name brokerCodes: #REF!
Name brokerCodesList: #REF!
Name brokerCodesListMaster: #REF!
Name brokerNames: #REF!
Name brokerNamesList: #REF!
Name brokerNamesListMaster: #REF!
Name Bubble: "Bubble"
Name calendarize: #REF!
Name calendarized: #REF!
Name calendarNames: #REF!

Sheet 联系方式及申明
A1: 数据库联系人：王先爽、文雪阳

Sheet 横向对比
A1: 注：一季报、三季报无连续的逾期、关注、重组、三阶段数据，假设以上规模与前一报告期保持一致
A2: 输入报告期 | B2: 46022 | C2: 上市银行 | D2: 国有行 | E2: 股份行 | F2: 城商行 | G2: 农商行 | H2: AH股 | I2: 纯H股 | J2: 国有1 | K2: 国有2 | L2: 国有3 | M2: 国有4 | N2: 国有5 | O2: 国有6 | P2: 股份1 | Q2: 股份2 | R2: 股份3 | S2: 股份4 | T2: 股份5 | U2: 股份6 | V2: 股份7 | W2: 股份8 | X2: 股份9 | Y2: 城商1 | Z2: 城商2 | AA2: 城商3 | AB2: 城商4 | AC2: 城商5 | AD2: 城商6 | AE2: 城商7 | AF2: 城商8 | AG2: 城商9 | AH2: 城商10 | AI2: 城商11 | AJ2: 城商12 | AK2: 城商13 | AL2: 城商14 | AM2: 城商15 | AN2: 城商16 | AO2: 城商17 | AP2: 农商1 | AQ2: 农商2 | AR2: 农商3 | AS2: 农商4 | AT2: 农商5 | AU2: 农商6 | AV2: 农商7 | AW2: 农商8 | AX2: 农商9 | AY2: 农商10 | AZ2: 纯H股1 | BA2: 纯H股2 | BB2: 纯H股3 | BC2: 纯H股4 | BD2: 纯H股5 | BE2: 纯H股6 | BF2: 纯H股7 | BG2: 纯H股8 | BH2: 纯H股9 | BI2: 纯H股10 | BJ2: 纯H股11 | BK2: 纯H股12 | BL2: 纯H股13
A3: 上市银行仅包括A股上市的42家银行 | B3: 单位：亿元 | J3: 1国有 | K3: 1国有 | L3: 1国有 | M3: 1国有 | N3: 1国有 | O3: 1国有 | P3: 2股份 | Q3: 2股份 | R3: 2股份 | S3: 2股份 | T3: 2股份 | U3: 2股份 | V3: 2股份 | W3: 2股份 | X3: 2股份 | Y3: 3城商 | Z3: 3城商 | AA3: 3城商 | AB3: 3城商 | AC3: 3城商 | AD3: 3城商 | AE3: 3城商 | AF3: 3城商 | AG3: 3城商 | AH3: 3城商 | AI3: 3城商 | AJ3: 3城商 | AK3: 3城商 | AL3: 3城商 | AM3: 3城商 | AN3: 3城商 | AO3: 3城商 | AP3: 4农商 | AQ3: 4农商 | AR3: 4农商 | AS3: 4农商 | AT3: 4农商 | AU3: 4农商 | AV3: 4农商 | AW3: 4农商 | AX3: 4农商 | AY3: 4农商
B4: =B2 -> 46022 | C4: 上市银行 | D4: 国有行 | E4: 股份行 | F4: 城商行 | G4: 农商行 | H4: =H2 -> AH股 | I4: =I2 -> 纯H股 | J4: 工商 | K4: 建设 | L4: 农业 | M4: 中国 | N4: 邮储 | O4: 交通 | P4: 招商 | Q4: 兴业 | R4: 浦发 | S4: 中信 | T4: 民生 | U4: 光大 | V4: 平安 | W4: 华夏 | X4: 浙商 | Y4: 北京 | Z4: 江苏 | AA4: 上海 | AB4: 宁波 | AC4: 南京 | AD4: 杭州 | AE4: 成都 | AF4: 长沙 | AG4: 重庆 | AH4: 贵阳 | AI4: 郑州 | AJ4: 苏州 | AK4: 青岛 | AL4: 齐鲁 | AM4: 兰州 | AN4: 西安 | AO4: 厦门 | AP4: 渝农 | AQ4: 沪农 | AR4: 青农 | AS4: 常熟 | AT4: 紫金 | AU4: 无锡 | AV4: 张家港 | AW4: 苏农 | AX4: 瑞丰 | AY4: 江阴 | AZ4: 中原 | BA4: 广州农商 | BB4: 天津 | BC4: 江西 | BD4: 泸州 | BE4: 甘肃 | BF4: 晋商 | BG4: 徽商 | BH4: 哈尔滨 | BI4: 贵州 | BJ4: 渤海 | BK4: 威海 | BL4: 东莞农商 | BO4: ="净利润TTM增速VS期初超额拨备利润倍数-"&TEXT(B2,"YYYY/MM") -> 净利润TTM增速VS期初超额拨备利润倍数-2025/12
A5: ① | B5: 贷款总额 | C5: =IFERROR(INDEX(【输出】数据汇总!$A:$AZ,MATCH(横向对比!C$4&横向对比!$B5,【输出】数据汇总!$A:$A,0),MATCH(横向对比!$B$4,【输出】数据汇总!$1:$1,0))/100,"") -> 1862821.1 | D5: =IFERROR(INDEX(【输出】数据汇总!$A:$AZ,MATCH(横向对比!D$4&横向对比!$B5,【输出】数据汇总!$A:$A,0),MATCH(横向对比!$B$4,【输出】数据汇总!$1:$1,0))/100,"") -> 1275931.8 | E5: =IFERROR(INDEX(【输出】数据汇总!$A:$AZ,MATCH(横向对比!E$4&横向对比!$B5,【输出】数据汇总!$A:$A,0),MATCH(横向对比!$B$4,【输出】数据汇总!$1:$1,0))/100,"") -> 410549.64 | F5: =IFERROR(INDEX(【输出】数据汇总!$A:$AZ,MATCH(横向对比!F$4&横向对比!$B5,【输出】数据汇总!$A:$A,0),MATCH(横向对比!$B$4,【输出】数据汇总!$1:$1,0))/100,"") -> 147599.65 | G5: =IFERROR(INDEX(【输出】数据汇总!$A:$AZ,MATCH(横向对比!G$4&横向对比!$B5,【输出】数据汇总!$A:$A,0),MATCH(横向对比!$B$4,【输出】数据汇总!$1:$1,0))/100,"") -> 28740.002 | H5: =IFERROR(INDEX(【输出】数据汇总!$A:$AZ,MATCH(横向对比!H$4&横向对比!$B5,【输出】数据汇总!$A:$A,0),MATCH(横向对比!$B$4,【输出】数据汇总!$1:$1,0))/100,"") | I5: =IFERROR(INDEX(【输出】数据汇总!$A:$AZ,MATCH(横向对比!I$4&横向对比!$B5,【输出】数据汇总!$A:$A,0),MATCH(横向对比!$B$4,【输出】数据汇总!$1:$1,0))/100,"") -> 63802.973 | J5: =IFERROR(INDEX(【输出】数据汇总!$A:$AZ,MATCH(横向对比!J$4&横向对比!$B5,【输出】数据汇总!$A:$A,0),MATCH(横向对比!$B$4,【输出】数据汇总!$1:$1,0))/100,"") -> 305061.14 | ... BL5: =IFERROR(INDEX(【输出】数据汇总!$A:$AZ,MATCH(横向对比!BL$4&横向对比!$B5,【输出】数据汇总!$A:$A,0),MATCH(横向对比!$B$4,【输出】数据汇总!$1:$1,0))/100,"") -> 4090.3122
A6: ② | B6: 逾期贷款余额 | C6: =IFERROR(INDEX(【输出】数据汇总!$A:$AZ,MATCH(横向对比!C$4&横向对比!$B6,【输出】数据汇总!$A:$A,0),MATCH(横向对比!$B$4,【输出】数据汇总!$1:$1,0))/100,"") -> 24524.321 | D6: =IFERROR(INDEX(【输出】数据汇总!$A:$AZ,MATCH(横向对比!D$4&横向对比!$B6,【输出】数据汇总!$A:$A,0),MATCH(横向对比!$B$4,【输出】数据汇总!$1:$1,0))/100,"") -> 17244.89 | E6: =IFERROR(INDEX(【输出】数据汇总!$A:$AZ,MATCH(横向对比!E$4&横向对比!$B6,【输出】数据汇总!$A:$A,0),MATCH(横向对比!$B$4,【输出】数据汇总!$1:$1,0))/100,"") -> 6818.95 | F6: =IFERROR(INDEX(【输出】数据汇总!$A:$AZ,MATCH(横向对比!F$4&横向对比!$B6,【输出】数据汇总!$A:$A,0),MATCH(横向对比!$B$4,【输出】数据汇总!$1:$1,0))/100,"") -> 296.20313 | G6: =IFERROR(INDEX(【输出】数据汇总!$A:$AZ,MATCH(横向对比!G$4&横向对比!$B6,【输出】数据汇总!$A:$A,0),MATCH(横向对比!$B$4,【输出】数据汇总!$1:$1,0))/100,"") -> 164.27824 | H6: =IFERROR(INDEX(【输出】数据汇总!$A:$AZ,MATCH(横向对比!H$4&横向对比!$B6,【输出】数据汇总!$A:$A,0),MATCH(横向对比!$B$4,【输出】数据汇总!$1:$1,0))/100,"") | I6: =IFERROR(INDEX(【输出】数据汇总!$A:$AZ,MATCH(横向对比!I$4&横向对比!$B6,【输出】数据汇总!$A:$A,0),MATCH(横向对比!$B$4,【输出】数据汇总!$1:$1,0))/100,"") -> 2052.1078 | J6: =IFERROR(INDEX(【输出】数据汇总!$A:$AZ,MATCH(横向对比!J$4&横向对比!$B6,【输出】数据汇总!$A:$A,0),MATCH(横向对比!$B$4,【输出】数据汇总!$1:$1,0))/100,"") -> 4627.35 | ... BL6: =IFERROR(INDEX(【输出】数据汇总!$A:$AZ,MATCH(横向对比!BL$4&横向对比!$B6,【输出】数据汇总!$A:$A,0),MATCH(横向对比!$B$4,【输出】数据汇总!$1:$1,0))/100,"") -> 94.75837
A7: ③ | B7: 重组贷款余额 | C7: =IFERROR(INDEX(【输出】数据汇总!$A:$AZ,MATCH(横向对比!C$4&横向对比!$B7,【输出】数据汇总!$A:$A,0),MATCH(横向对比!$B$4,【输出】数据汇总!$1:$1,0))/100,"") -> 9099.3913 | D7: =IFERROR(INDEX(【输出】数据汇总!$A:$AZ,MATCH(横向对比!D$4&横向对比!$B7,【输出】数据汇总!$A:$A,0),MATCH(横向对比!$B$4,【输出】数据汇总!$1:$1,0))/100,"") -> 6406.08 | E7: =IFERROR(INDEX(【输出】数据汇总!$A:$AZ,MATCH(横向对比!E$4&横向对比!$B7,【输出】数据汇总!$A:$A,0),MATCH(横向对比!$B$4,【输出】数据汇总!$1:$1,0))/100,"") -> 2636.12 | F7: =IFERROR(INDEX(【输出】数据汇总!$A:$AZ,MATCH(横向对比!F$4&横向对比!$B7,【输出】数据汇总!$A:$A,0),MATCH(横向对比!$B$4,【输出】数据汇总!$1:$1,0))/100,"") -> 10.88911 | G7: =IFERROR(INDEX(【输出】数据汇总!$A:$AZ,MATCH(横向对比!G$4&横向对比!$B7,【输出】数据汇总!$A:$A,0),MATCH(横向对比!$B$4,【输出】数据汇总!$1:$1,0))/100,"") -> 46.302178 | H7: =IFERROR(INDEX(【输出】数据汇总!$A:$AZ,MATCH(横向对比!H$4&横向对比!$B7,【输出】数据汇总!$A:$A,0),MATCH(横向对比!$B$4,【输出】数据汇总!$1:$1,0))/100,"") | I7: =IFERROR(INDEX(【输出】数据汇总!$A:$AZ,MATCH(横向对比!I$4&横向对比!$B7,【输出】数据汇总!$A:$A,0),MATCH(横向对比!$B$4,【输出】数据汇总!$1:$1,0))/100,"") -> 695.65569 | J7: =IFERROR(INDEX(【输出】数据汇总!$A:$AZ,MATCH(横向对比!J$4&横向对比!$B7,【输出】数据汇总!$A:$A,0),MATCH(横向对比!$B$4,【输出】数据汇总!$1:$1,0))/100,"") -> 1560.27 | ... BL7: =IFERROR(INDEX(【输出】数据汇总!$A:$AZ,MATCH(横向对比!BL$4&横向对比!$B7,【输出】数据汇总!$A:$A,0),MATCH(横向对比!$B$4,【输出】数据汇总!$1:$1,0))/100,"") -> 8.85676
A8: ④ | B8: 不良贷款余额 | C8: =IFERROR(INDEX(【输出】数据汇总!$A:$AZ,MATCH(横向对比!C$4&横向对比!$B8,【输出】数据汇总!$A:$A,0),MATCH(横向对比!$B$4,【输出】数据汇总!$1:$1,0))/100,"") -> 21227.878 | D8: =IFERROR(INDEX(【输出】数据汇总!$A:$AZ,MATCH(横向对比!D$4&横向对比!$B8,【输出】数据汇总!$A:$A,0),MATCH(横向对比!$B$4,【输出】数据汇总!$1:$1,0))/100,"") -> 16029.94 | E8: =IFERROR(INDEX(【输出】数据汇总!$A:$AZ,MATCH(横向对比!E$4&横向对比!$B8,【输出】数据汇总!$A:$A,0),MATCH(横向对比!$B$4,【输出】数据汇总!$1:$1,0))/100,"") -> 4901.85 | F8: =IFERROR(INDEX(【输出】数据汇总!$A:$AZ,MATCH(横向对比!F$4&横向对比!$B8,【输出】数据汇总!$A:$A,0),MATCH(横向对比!$B$4,【输出】数据汇总!$1:$1,0))/100,"") -> 169.04226 | G8: =IFERROR(INDEX(【输出】数据汇总!$A:$AZ,MATCH(横向对比!G$4&横向对比!$B8,【输出】数据汇总!$A:$A,0),MATCH(横向对比!$B$4,【输出】数据汇总!$1:$1,0))/100,"") -> 127.04607 | H8: =IFERROR(INDEX(【输出】数据汇总!$A:$AZ,MATCH(横向对比!H$4&横向对比!$B8,【输出】数据汇总!$A:$A,0),MATCH(横向对比!$B$4,【输出】数据汇总!$1:$1,0))/100,"") | I8: =IFERROR(INDEX(【输出】数据汇总!$A:$AZ,MATCH(横向对比!I$4&横向对比!$B8,【输出】数据汇总!$A:$A,0),MATCH(横向对比!$B$4,【输出】数据汇总!$1:$1,0))/100,"") -> 1085.1866 | J8: =IFERROR(INDEX(【输出】数据汇总!$A:$AZ,MATCH(横向对比!J$4&横向对比!$B8,【输出】数据汇总!$A:$A,0),MATCH(横向对比!$B$4,【输出】数据汇总!$1:$1,0))/100,"") -> 3990.13 | ... BL8: =IFERROR(INDEX(【输出】数据汇总!$A:$AZ,MATCH(横向对比!BL$4&横向对比!$B8,【输出】数据汇总!$A:$A,0),MATCH(横向对比!$B$4,【输出】数据汇总!$1:$1,0))/100,"") -> 73.216589
A9: ⑤ | B9: 关注类贷款余额 | C9: =IFERROR(INDEX(【输出】数据汇总!$A:$AZ,MATCH(横向对比!C$4&横向对比!$B9,【输出】数据汇总!$A:$A,0),MATCH(横向对比!$B$4,【输出】数据汇总!$1:$1,0))/100,"") -> 29337.196 | D9: =IFERROR(INDEX(【输出】数据汇总!$A:$AZ,MATCH(横向对比!D$4&横向对比!$B9,【输出】数据汇总!$A:$A,0),MATCH(横向对比!$B$4,【输出】数据汇总!$1:$1,0))/100,"") -> 21089.63 | E9: =IFERROR(INDEX(【输出】数据汇总!$A:$AZ,MATCH(横向对比!E$4&横向对比!$B9,【输出】数据汇总!$A:$A,0),MATCH(横向对比!$B$4,【输出】数据汇总!$1:$1,0))/100,"") -> 7867.03 | F9: =IFERROR(INDEX(【输出】数据汇总!$A:$AZ,MATCH(横向对比!F$4&横向对比!$B9,【输出】数据汇总!$A:$A,0),MATCH(横向对比!$B$4,【输出】数据汇总!$1:$1,0))/100,"") -> 207.84482 | G9: =IFERROR(INDEX(【输出】数据汇总!$A:$AZ,MATCH(横向对比!G$4&横向对比!$B9,【输出】数据汇总!$A:$A,0),MATCH(横向对比!$B$4,【输出】数据汇总!$1:$1,0))/100,"") -> 172.69087 | H9: =IFERROR(INDEX(【输出】数据汇总!$A:$AZ,MATCH(横向对比!H$4&横向对比!$B9,【输出】数据汇总!$A:$A,0),MATCH(横向对比!$B$4,【输出】数据汇总!$1:$1,0))/100,"") | I9: =IFERROR(INDEX(【输出】数据汇总!$A:$AZ,MATCH(横向对比!I$4&横向对比!$B9,【输出】数据汇总!$A:$A,0),MATCH(横向对比!$B$4,【输出】数据汇总!$1:$1,0))/100,"") -> 1860.9933 | J9: =IFERROR(INDEX(【输出】数据汇总!$A:$AZ,MATCH(横向对比!J$4&横向对比!$B9,【输出】数据汇总!$A:$A,0),MATCH(横向对比!$B$4,【输出】数据汇总!$1:$1,0))/100,"") -> 5946.56 | ... BL9: =IFERROR(INDEX(【输出】数据汇总!$A:$AZ,MATCH(横向对比!BL$4&横向对比!$B9,【输出】数据汇总!$A:$A,0),MATCH(横向对比!$B$4,【输出】数据汇总!$1:$1,0))/100,"") -> 87.20042
A10: ⑥=MAX(②+③，④+⑤) | B10: 广义风险贷款 | C10: =MAX(C6+C7,C8+C9) -> 50565.074 | D10: =MAX(D6+D7,D8+D9) -> 37119.57 | E10: =MAX(E6+E7,E8+E9) -> 12768.88 | F10: =MAX(F6+F7,F8+F9) -> 376.88708 | G10: =MAX(G6+G7,G8+G9) -> 299.73694 | H10: =MAX(H6+H7,H8+H9) -> #VALUE! | I10: =MAX(I6+I7,I8+I9) -> 2946.1799 | J10: =IFERROR(INDEX(【输出】数据汇总!$A:$AZ,MATCH(横向对比!J$4&横向对比!$B10,【输出】数据汇总!$A:$A,0),MATCH(横向对比!$B$4,【输出】数据汇总!$1:$1,0))/100,"") -> 9942.8609 | K10: =IFERROR(INDEX(【输出】数据汇总!$A:$AZ,MATCH(横向对比!K$4&横向对比!$B10,【输出】数据汇总!$A:$A,0),MATCH(横向对比!$B$4,【输出】数据汇总!$1:$1,0))/100,"") -> 8545.5503 | L10: =IFERROR(INDEX(【输出】数据汇总!$A:$AZ,MATCH(横向对比!L$4&横向对比!$B10,【输出】数据汇总!$A:$A,0),MATCH(横向对比!$B$4,【输出】数据汇总!$1:$1,0))/100,"") -> 7222.2739 | M10: =IFERROR(INDEX(【输出】数据汇总!$A:$AZ,MATCH(横向对比!M$4&横向对比!$B10,【输出】数据汇总!$A:$A,0),MATCH(横向对比!$B$4,【输出】数据汇总!$1:$1,0))/100,"") -> 6313.8242 | N10: =IFERROR(INDEX(【输出】数据汇总!$A:$AZ,MATCH(横向对比!N$4&横向对比!$B10,【输出】数据汇总!$A:$A,0),MATCH(横向对比!$B$4,【输出】数据汇总!$1:$1,0))/100,"") -> 2433.07 | O10: =IFERROR(INDEX(【输出】数据汇总!$A:$AZ,MATCH(横向对比!O$4&横向对比!$B10,【输出】数据汇总!$A:$A,0),MATCH(横向对比!$B$4,【输出】数据汇总!$1:$1,0))/100,"") -> 2676.2471 | P10: =IFERROR(INDEX(【输出】数据汇总!$A:$AZ,MATCH(横向对比!P$4&横向对比!$B10,【输出】数据汇总!$A:$A,0),MATCH(横向对比!$B$4,【输出】数据汇总!$1:$1,0))/100,"") -> 1720.8575 | Q10: =IFERROR(INDEX(【输出】数据汇总!$A:$AZ,MATCH(横向对比!Q$4&横向对比!$B10,【输出】数据汇总!$A:$A,0),MATCH(横向对比!$B$4,【输出】数据汇总!$1:$1,0))/100,"") -> 1646.4053 | ... BL10: =IFERROR(INDEX(【输出】数据汇总!$A:$AZ,MATCH(横向对比!BL$4&横向对比!$B10,【输出】数据汇总!$A:$A,0),MATCH(横向对比!$B$4,【输出】数据汇总!$1:$1,0))/100,"") -> 160.41701
A11: ⑦ | B11: 非信贷资产第三阶段额 | C11: =IFERROR(INDEX(【输出】数据汇总!$A:$AZ,MATCH(横向对比!C$4&横向对比!$B11,【输出】数据汇总!$A:$A,0),MATCH(横向对比!$B$4,【输出】数据汇总!$1:$1,0))/100,"") -> 4130.8113 | D11: =IFERROR(INDEX(【输出】数据汇总!$A:$AZ,MATCH(横向对比!D$4&横向对比!$B11,【输出】数据汇总!$A:$A,0),MATCH(横向对比!$B$4,【输出】数据汇总!$1:$1,0))/100,"") -> 512.63 | E11: =IFERROR(INDEX(【输出】数据汇总!$A:$AZ,MATCH(横向对比!E$4&横向对比!$B11,【输出】数据汇总!$A:$A,0),MATCH(横向对比!$B$4,【输出】数据汇总!$1:$1,0))/100,"") -> 2695.32 | F11: =IFERROR(INDEX(【输出】数据汇总!$A:$AZ,MATCH(横向对比!F$4&横向对比!$B11,【输出】数据汇总!$A:$A,0),MATCH(横向对比!$B$4,【输出】数据汇总!$1:$1,0))/100,"") -> 898.88537 | G11: =IFERROR(INDEX(【输出】数据汇总!$A:$AZ,MATCH(横向对比!G$4&横向对比!$B11,【输出】数据汇总!$A:$A,0),MATCH(横向对比!$B$4,【输出】数据汇总!$1:$1,0))/100,"") -> 23.97595 | H11: =IFERROR(INDEX(【输出】数据汇总!$A:$AZ,MATCH(横向对比!H$4&横向对比!$B11,【输出】数据汇总!$A:$A,0),MATCH(横向对比!$B$4,【输出】数据汇总!$1:$1,0))/100,"") | I11: =IFERROR(INDEX(【输出】数据汇总!$A:$AZ,MATCH(横向对比!I$4&横向对比!$B11,【输出】数据汇总!$A:$A,0),MATCH(横向对比!$B$4,【输出】数据汇总!$1:$1,0))/100,"") -> 1038.2064 | J11: =IFERROR(INDEX(【输出】数据汇总!$A:$AZ,MATCH(横向对比!J$4&横向对比!$B11,【输出】数据汇总!$A:$A,0),MATCH(横向对比!$B$4,【输出】数据汇总!$1:$1,0))/100,"") -> 35.42 | ... BL11: =IFERROR(INDEX(【输出】数据汇总!$A:$AZ,MATCH(横向对比!BL$4&横向对比!$B11,【输出】数据汇总!$A:$A,0),MATCH(横向对比!$B$4,【输出】数据汇总!$1:$1,0))/100,"") -> 0.74179
A12: ⑧ | B12: 贷款拨备额 | C12: =IFERROR(INDEX(【输出】数据汇总!$A:$AZ,MATCH(横向对比!C$4&横向对比!$B12,【输出】数据汇总!$A:$A,0),MATCH(横向对比!$B$4,【输出】数据汇总!$1:$1,0))/100,"") -> 51227.472 | D12: =IFERROR(INDEX(【输出】数据汇总!$A:$AZ,MATCH(横向对比!D$4&横向对比!$B12,【输出】数据汇总!$A:$A,0),MATCH(横向对比!$B$4,【输出】数据汇总!$1:$1,0))/100,"") -> 39815.4 | E12: =IFERROR(INDEX(【输出】数据汇总!$A:$AZ,MATCH(横向对比!E$4&横向对比!$B12,【输出】数据汇总!$A:$A,0),MATCH(横向对比!$B$4,【输出】数据汇总!$1:$1,0))/100,"") -> 10559.18 | F12: =IFERROR(INDEX(【输出】数据汇总!$A:$AZ,MATCH(横向对比!F$4&横向对比!$B12,【输出】数据汇总!$A:$A,0),MATCH(横向对比!$B$4,【输出】数据汇总!$1:$1,0))/100,"") -> 391.06529 | G12: =IFERROR(INDEX(【输出】数据汇总!$A:$AZ,MATCH(横向对比!G$4&横向对比!$B12,【输出】数据汇总!$A:$A,0),MATCH(横向对比!$B$4,【输出】数据汇总!$1:$1,0))/100,"") -> 461.82664 | H12: =IFERROR(INDEX(【输出】数据汇总!$A:$AZ,MATCH(横向对比!H$4&横向对比!$B12,【输出】数据汇总!$A:$A,0),MATCH(横向对比!$B$4,【输出】数据汇总!$1:$1,0))/100,"") | I12: =IFERROR(INDEX(【输出】数据汇总!$A:$AZ,MATCH(横向对比!I$4&横向对比!$B12,【输出】数据汇总!$A:$A,0),MATCH(横向对比!$B$4,【输出】数据汇总!$1:$1,0))/100,"") -> 2142.1342 | J12: =IFERROR(INDEX(【输出】数据汇总!$A:$AZ,MATCH(横向对比!J$4&横向对比!$B12,【输出】数据汇总!$A:$A,0),MATCH(横向对比!$B$4,【输出】数据汇总!$1:$1,0))/100,"") -> 8522.74 | ... BL12: =IFERROR(INDEX(【输出】数据汇总!$A:$AZ,MATCH(横向对比!BL$4&横向对比!$B12,【输出】数据汇总!$A:$A,0),MATCH(横向对比!$B$4,【输出】数据汇总!$1:$1,0))/100,"") -> 151.09982
A13: ⑨=⑧-⑥*100% | B13: 超额贷款拨备额 | C13: =IFERROR(C12-C10*100%,"") -> 662.39791 | D13: =IFERROR(D12-D10*100%,"") -> 2695.83 | E13: =IFERROR(E12-E10*100%,"") -> -2209.7 | F13: =IFERROR(F12-F10*100%,"") -> 14.17821 | G13: =IFERROR(G12-G10*100%,"") -> 162.0897 | H13: =IFERROR(H12-H10*100%,"") | I13: =IFERROR(I12-I10*100%,"") -> -804.04571 | J13: =IFERROR(J12-J10*100%,"") -> -1420.1209 | ... BL13: =IFERROR(BL12-BL10*100%,"") -> -9.3171893
A14: ⑦ | B14: 非信贷资产第三阶段额 | C14: =IFERROR(INDEX(【输出】数据汇总!$A:$AZ,MATCH(横向对比!C$4&横向对比!$B14,【输出】数据汇总!$A:$A,0),MATCH(横向对比!$B$4,【输出】数据汇总!$1:$1,0))/100,"") -> 4130.8113 | D14: =IFERROR(INDEX(【输出】数据汇总!$A:$AZ,MATCH(横向对比!D$4&横向对比!$B14,【输出】数据汇总!$A:$A,0),MATCH(横向对比!$B$4,【输出】数据汇总!$1:$1,0))/100,"") -> 512.63 | E14: =IFERROR(INDEX(【输出】数据汇总!$A:$AZ,MATCH(横向对比!E$4&横向对比!$B14,【输出】数据汇总!$A:$A,0),MATCH(横向对比!$B$4,【输出】数据汇总!$1:$1,0))/100,"") -> 2695.32 | F14: =IFERROR(INDEX(【输出】数据汇总!$A:$AZ,MATCH(横向对比!F$4&横向对比!$B14,【输出】数据汇总!$A:$A,0),MATCH(横向对比!$B$4,【输出】数据汇总!$1:$1,0))/100,"") -> 898.88537 | G14: =IFERROR(INDEX(【输出】数据汇总!$A:$AZ,MATCH(横向对比!G$4&横向对比!$B14,【输出】数据汇总!$A:$A,0),MATCH(横向对比!$B$4,【输出】数据汇总!$1:$1,0))/100,"") -> 23.97595 | H14: =IFERROR(INDEX(【输出】数据汇总!$A:$AZ,MATCH(横向对比!H$4&横向对比!$B14,【输出】数据汇总!$A:$A,0),MATCH(横向对比!$B$4,【输出】数据汇总!$1:$1,0))/100,"") | I14: =IFERROR(INDEX(【输出】数据汇总!$A:$AZ,MATCH(横向对比!I$4&横向对比!$B14,【输出】数据汇总!$A:$A,0),MATCH(横向对比!$B$4,【输出】数据汇总!$1:$1,0))/100,"") -> 1038.2064 | J14: =IFERROR(INDEX(【输出】数据汇总!$A:$AZ,MATCH(横向对比!J$4&横向对比!$B14,【输出】数据汇总!$A:$A,0),MATCH(横向对比!$B$4,【输出】数据汇总!$1:$1,0))/100,"") -> 35.42 | ... BL14: =IFERROR(INDEX(【输出】数据汇总!$A:$AZ,MATCH(横向对比!BL$4&横向对比!$B14,【输出】数据汇总!$A:$A,0),MATCH(横向对比!$B$4,【输出】数据汇总!$1:$1,0))/100,"") -> 0.74179
A15: ⑩ | B15: 非信贷拨备额 | C15: =IFERROR(INDEX(【输出】数据汇总!$A:$AZ,MATCH(横向对比!C$4&横向对比!$B15,【输出】数据汇总!$A:$A,0),MATCH(横向对比!$B$4,【输出】数据汇总!$1:$1,0))/100,"") -> 3084.47 | D15: =IFERROR(INDEX(【输出】数据汇总!$A:$AZ,MATCH(横向对比!D$4&横向对比!$B15,【输出】数据汇总!$A:$A,0),MATCH(横向对比!$B$4,【输出】数据汇总!$1:$1,0))/100,"") -> 54.89 | E15: =IFERROR(INDEX(【输出】数据汇总!$A:$AZ,MATCH(横向对比!E$4&横向对比!$B15,【输出】数据汇总!$A:$A,0),MATCH(横向对比!$B$4,【输出】数据汇总!$1:$1,0))/100,"") -> 3029.58 | F15: =IFERROR(INDEX(【输出】数据汇总!$A:$AZ,MATCH(横向对比!F$4&横向对比!$B15,【输出】数据汇总!$A:$A,0),MATCH(横向对比!$B$4,【输出】数据汇总!$1:$1,0))/100,"") | G15: =IFERROR(INDEX(【输出】数据汇总!$A:$AZ,MATCH(横向对比!G$4&横向对比!$B15,【输出】数据汇总!$A:$A,0),MATCH(横向对比!$B$4,【输出】数据汇总!$1:$1,0))/100,"") | H15: =IFERROR(INDEX(【输出】数据汇总!$A:$AZ,MATCH(横向对比!H$4&横向对比!$B15,【输出】数据汇总!$A:$A,0),MATCH(横向对比!$B$4,【输出】数据汇总!$1:$1,0))/100,"") | I15: =IFERROR(INDEX(【输出】数据汇总!$A:$AZ,MATCH(横向对比!I$4&横向对比!$B15,【输出】数据汇总!$A:$A,0),MATCH(横向对比!$B$4,【输出】数据汇总!$1:$1,0))/100,"") -> 988.42977 | J15: =IFERROR(INDEX(【输出】数据汇总!$A:$AZ,MATCH(横向对比!J$4&横向对比!$B15,【输出】数据汇总!$A:$A,0),MATCH(横向对比!$B$4,【输出】数据汇总!$1:$1,0))/100,"") -> 979.66 | ... BL15: =IFERROR(INDEX(【输出】数据汇总!$A:$AZ,MATCH(横向对比!BL$4&横向对比!$B15,【输出】数据汇总!$A:$A,0),MATCH(横向对比!$B$4,【输出】数据汇总!$1:$1,0))/100,"") -> 5.84178
A16: ⑪=⑩-⑦*100% | B16: 超额非信贷拨备 | C16: =IFERROR(IF(C14="",C15-0,C15-C14*100%),"") -> -1046.3413 | D16: =IFERROR(IF(D14="",D15-0,D15-D14*100%),"") -> -457.74 | E16: =IFERROR(IF(E14="",E15-0,E15-E14*100%),"") -> 334.26 | F16: =IFERROR(IF(F14="",F15-0,F15-F14*100%),"") | G16: =IFERROR(IF(G14="",G15-0,G15-G14*100%),"") | H16: =IFERROR(IF(H14="",H15-0,H15-H14*100%),"") | I16: =IFERROR(IF(I14="",I15-0,I15-I14*100%),"") -> -49.7766 | J16: =IFERROR(IF(J14="",J15-0,J15-J14*100%),"") -> 944.24 | ... BL16: =IFERROR(IF(BL14="",BL15-0,BL15-BL14*100%),"") -> 5.09999
A17: ⑪+⑨ | B17: 超额拨备额 | C17: =IFERROR(C13+C16,"") -> -383.9434 | D17: =IFERROR(D13+D16,"") -> 2238.09 | E17: =IFERROR(E13+E16,"") -> -1875.44 | F17: =IFERROR(F13+F16,"") | G17: =IFERROR(G13+G16,"") | H17: =IFERROR(H13+H16,"") | I17: =IFERROR(I13+I16,"") -> -853.82231 | J17: =IFERROR(J13+J16,"") -> -475.88093 | ... BL17: =IFERROR(BL13+BL16,"") -> -4.2171993
B18: 归母净利润(TTM) | C18: =IFERROR(INDEX(【输出】数据汇总!$A:$AZ,MATCH(横向对比!C$4&横向对比!$B18,【输出】数据汇总!$A:$A,0),MATCH(横向对比!$B$4,【输出】数据汇总!$1:$1,0))/100,"") -> 20608.668 | D18: =IFERROR(INDEX(【输出】数据汇总!$A:$AZ,MATCH(横向对比!D$4&横向对比!$B18,【输出】数据汇总!$A:$A,0),MATCH(横向对比!$B$4,【输出】数据汇总!$1:$1,0))/100,"") -> 14245.56 | E18: =IFERROR(INDEX(【输出】数据汇总!$A:$AZ,MATCH(横向对比!E$4&横向对比!$B18,【输出】数据汇总!$A:$A,0),MATCH(横向对比!$B$4,【输出】数据汇总!$1:$1,0))/100,"") -> 5004.38 | F18: =IFERROR(INDEX(【输出】数据汇总!$A:$AZ,MATCH(横向对比!F$4&横向对比!$B18,【输出】数据汇总!$A:$A,0),MATCH(横向对比!$B$4,【输出】数据汇总!$1:$1,0))/100,"") -> 1154.4745 | G18: =IFERROR(INDEX(【输出】数据汇总!$A:$AZ,MATCH(横向对比!G$4&横向对比!$B18,【输出】数据汇总!$A:$A,0),MATCH(横向对比!$B$4,【输出】数据汇总!$1:$1,0))/100,"") -> 204.25364 | H18: =IFERROR(INDEX(【输出】数据汇总!$A:$AZ,MATCH(横向对比!H$4&横向对比!$B18,【输出】数据汇总!$A:$A,0),MATCH(横向对比!$B$4,【输出】数据汇总!$1:$1,0))/100,"") | I18: =IFERROR(INDEX(【输出】数据汇总!$A:$AZ,MATCH(横向对比!I$4&横向对比!$B18,【输出】数据汇总!$A:$A,0),MATCH(横向对比!$B$4,【输出】数据汇总!$1:$1,0))/100,"") -> 476.31644 | J18: =IFERROR(INDEX(【输出】数据汇总!$A:$AZ,MATCH(横向对比!J$4&横向对比!$B18,【输出】数据汇总!$A:$A,0),MATCH(横向对比!$B$4,【输出】数据汇总!$1:$1,0))/100,"") -> 3685.62 | ... BL18: =IFERROR(INDEX(【输出】数据汇总!$A:$AZ,MATCH(横向对比!BL$4&横向对比!$B18,【输出】数据汇总!$A:$A,0),MATCH(横向对比!$B$4,【输出】数据汇总!$1:$1,0))/100,"") -> 38.53908
B19: 归母净资产 | C19: =IFERROR(INDEX(【输出】数据汇总!$A:$AZ,MATCH(横向对比!C$4&横向对比!$B19,【输出】数据汇总!$A:$A,0),MATCH(横向对比!$B$4,【输出】数据汇总!$1:$1,0))/100,"") -> 242495.04 | D19: =IFERROR(INDEX(【输出】数据汇总!$A:$AZ,MATCH(横向对比!D$4&横向对比!$B19,【输出】数据汇总!$A:$A,0),MATCH(横向对比!$B$4,【输出】数据汇总!$1:$1,0))/100,"") -> 166382.74 | E19: =IFERROR(INDEX(【输出】数据汇总!$A:$AZ,MATCH(横向对比!E$4&横向对比!$B19,【输出】数据汇总!$A:$A,0),MATCH(横向对比!$B$4,【输出】数据汇总!$1:$1,0))/100,"") -> 62645.53 | F19: =IFERROR(INDEX(【输出】数据汇总!$A:$AZ,MATCH(横向对比!F$4&横向对比!$B19,【输出】数据汇总!$A:$A,0),MATCH(横向对比!$B$4,【输出】数据汇总!$1:$1,0))/100,"") -> 11274.123 | G19: =IFERROR(INDEX(【输出】数据汇总!$A:$AZ,MATCH(横向对比!G$4&横向对比!$B19,【输出】数据汇总!$A:$A,0),MATCH(横向对比!$B$4,【输出】数据汇总!$1:$1,0))/100,"") -> 2192.6507 | H19: =IFERROR(INDEX(【输出】数据汇总!$A:$AZ,MATCH(横向对比!H$4&横向对比!$B19,【输出】数据汇总!$A:$A,0),MATCH(横向对比!$B$4,【输出】数据汇总!$1:$1,0))/100,"") | I19: =IFERROR(INDEX(【输出】数据汇总!$A:$AZ,MATCH(横向对比!I$4&横向对比!$B19,【输出】数据汇总!$A:$A,0),MATCH(横向对比!$B$4,【输出】数据汇总!$1:$1,0))/100,"") -> 8837.0222 | J19: =IFERROR(INDEX(【输出】数据汇总!$A:$AZ,MATCH(横向对比!J$4&横向对比!$B19,【输出】数据汇总!$A:$A,0),MATCH(横向对比!$B$4,【输出】数据汇总!$1:$1,0))/100,"") -> 42442.59 | ... BL19: =IFERROR(INDEX(【输出】数据汇总!$A:$AZ,MATCH(横向对比!BL$4&横向对比!$B19,【输出】数据汇总!$A:$A,0),MATCH(横向对比!$B$4,【输出】数据汇总!$1:$1,0))/100,"") -> 602.94841
B20: 逾期率 | C20: =IFERROR(INDEX(【输出】数据汇总!$A:$AZ,MATCH(横向对比!C$4&横向对比!$B20,【输出】数据汇总!$A:$A,0),MATCH(横向对比!$B$4,【输出】数据汇总!$1:$1,0)),"") -> 0.01586935 | D20: =IFERROR(INDEX(【输出】数据汇总!$A:$AZ,MATCH(横向对比!D$4&横向对比!$B20,【输出】数据汇总!$A:$A,0),MATCH(横向对比!$B$4,【输出】数据汇总!$1:$1,0)),"") -> 0.013524708 | E20: =IFERROR(INDEX(【输出】数据汇总!$A:$AZ,MATCH(横向对比!E$4&横向对比!$B20,【输出】数据汇总!$A:$A,0),MATCH(横向对比!$B$4,【输出】数据汇总!$1:$1,0)),"") -> 0.017091767 | F20: =IFERROR(INDEX(【输出】数据汇总!$A:$AZ,MATCH(横向对比!F$4&横向对比!$B20,【输出】数据汇总!$A:$A,0),MATCH(横向对比!$B$4,【输出】数据汇总!$1:$1,0)),"") -> 0.017350052 | G20: =IFERROR(INDEX(【输出】数据汇总!$A:$AZ,MATCH(横向对比!G$4&横向对比!$B20,【输出】数据汇总!$A:$A,0),MATCH(横向对比!$B$4,【输出】数据汇总!$1:$1,0)),"") -> 0.015510873 | H20: =IFERROR(INDEX(【输出】数据汇总!$A:$AZ,MATCH(横向对比!H$4&横向对比!$B20,【输出】数据汇总!$A:$A,0),MATCH(横向对比!$B$4,【输出】数据汇总!$1:$1,0)),"") | I20: =IFERROR(INDEX(【输出】数据汇总!$A:$AZ,MATCH(横向对比!I$4&横向对比!$B20,【输出】数据汇总!$A:$A,0),MATCH(横向对比!$B$4,【输出】数据汇总!$1:$1,0)),"") -> 0.032596739 | J20: =IFERROR(INDEX(【输出】数据汇总!$A:$AZ,MATCH(横向对比!J$4&横向对比!$B20,【输出】数据汇总!$A:$A,0),MATCH(横向对比!$B$4,【输出】数据汇总!$1:$1,0)),"") -> 0.015168599 | ... BL20: =IFERROR(INDEX(【输出】数据汇总!$A:$AZ,MATCH(横向对比!BL$4&横向对比!$B20,【输出】数据汇总!$A:$A,0),MATCH(横向对比!$B$4,【输出】数据汇总!$1:$1,0)),"") -> 0.023166537
B21: 重组率 | C21: =IFERROR(INDEX(【输出】数据汇总!$A:$AZ,MATCH(横向对比!C$4&横向对比!$B21,【输出】数据汇总!$A:$A,0),MATCH(横向对比!$B$4,【输出】数据汇总!$1:$1,0)),"") -> 0.003969853 | D21: =IFERROR(INDEX(【输出】数据汇总!$A:$AZ,MATCH(横向对比!D$4&横向对比!$B21,【输出】数据汇总!$A:$A,0),MATCH(横向对比!$B$4,【输出】数据汇总!$1:$1,0)),"") -> 0.0051598449 | E21: =IFERROR(INDEX(【输出】数据汇总!$A:$AZ,MATCH(横向对比!E$4&横向对比!$B21,【输出】数据汇总!$A:$A,0),MATCH(横向对比!$B$4,【输出】数据汇总!$1:$1,0)),"") -> 0.0067544424 | F21: =IFERROR(INDEX(【输出】数据汇总!$A:$AZ,MATCH(横向对比!F$4&横向对比!$B21,【输出】数据汇总!$A:$A,0),MATCH(横向对比!$B$4,【输出】数据汇总!$1:$1,0)),"") -> 0.0010841402 | G21: =IFERROR(INDEX(【输出】数据汇总!$A:$AZ,MATCH(横向对比!G$4&横向对比!$B21,【输出】数据汇总!$A:$A,0),MATCH(横向对比!$B$4,【输出】数据汇总!$1:$1,0)),"") -> 0.0028809844 | H21: =IFERROR(INDEX(【输出】数据汇总!$A:$AZ,MATCH(横向对比!H$4&横向对比!$B21,【输出】数据汇总!$A:$A,0),MATCH(横向对比!$B$4,【输出】数据汇总!$1:$1,0)),"") | I21: =IFERROR(INDEX(【输出】数据汇总!$A:$AZ,MATCH(横向对比!I$4&横向对比!$B21,【输出】数据汇总!$A:$A,0),MATCH(横向对比!$B$4,【输出】数据汇总!$1:$1,0)),"") -> 0.010163036 | J21: =IFERROR(INDEX(【输出】数据汇总!$A:$AZ,MATCH(横向对比!J$4&横向对比!$B21,【输出】数据汇总!$A:$A,0),MATCH(横向对比!$B$4,【输出】数据汇总!$1:$1,0)),"") -> 0.0051146141 | ... BL21: =IFERROR(INDEX(【输出】数据汇总!$A:$AZ,MATCH(横向对比!BL$4&横向对比!$B21,【输出】数据汇总!$A:$A,0),MATCH(横向对比!$B$4,【输出】数据汇总!$1:$1,0)),"") -> 0.0021653017
B22: 不良贷款率 | C22: =IFERROR(INDEX(【输出】数据汇总!$A:$AZ,MATCH(横向对比!C$4&横向对比!$B22,【输出】数据汇总!$A:$A,0),MATCH(横向对比!$B$4,【输出】数据汇总!$1:$1,0)),"") -> 0.011705556 | D22: =IFERROR(INDEX(【输出】数据汇总!$A:$AZ,MATCH(横向对比!D$4&横向对比!$B22,【输出】数据汇总!$A:$A,0),MATCH(横向对比!$B$4,【输出】数据汇总!$1:$1,0)),"") -> 0.01225 | E22: =IFERROR(INDEX(【输出】数据汇总!$A:$AZ,MATCH(横向对比!E$4&横向对比!$B22,【输出】数据汇总!$A:$A,0),MATCH(横向对比!$B$4,【输出】数据汇总!$1:$1,0)),"") -> 0.012388889 | F22: =IFERROR(INDEX(【输出】数据汇总!$A:$AZ,MATCH(横向对比!F$4&横向对比!$B22,【输出】数据汇总!$A:$A,0),MATCH(横向对比!$B$4,【输出】数据汇总!$1:$1,0)),"") -> 0.012733333 | G22: =IFERROR(INDEX(【输出】数据汇总!$A:$AZ,MATCH(横向对比!G$4&横向对比!$B22,【输出】数据汇总!$A:$A,0),MATCH(横向对比!$B$4,【输出】数据汇总!$1:$1,0)),"") -> 0.00945 | H22: =IFERROR(INDEX(【输出】数据汇总!$A:$AZ,MATCH(横向对比!H$4&横向对比!$B22,【输出】数据汇总!$A:$A,0),MATCH(横向对比!$B$4,【输出】数据汇总!$1:$1,0)),"") | I22: =IFERROR(INDEX(【输出】数据汇总!$A:$AZ,MATCH(横向对比!I$4&横向对比!$B22,【输出】数据汇总!$A:$A,0),MATCH(横向对比!$B$4,【输出】数据汇总!$1:$1,0)),"") -> 0.017592308 | J22: =IFERROR(INDEX(【输出】数据汇总!$A:$AZ,MATCH(横向对比!J$4&横向对比!$B22,【输出】数据汇总!$A:$A,0),MATCH(横向对比!$B$4,【输出】数据汇总!$1:$1,0)),"") -> 0.0131 | ... BL22: =IFERROR(INDEX(【输出】数据汇总!$A:$AZ,MATCH(横向对比!BL$4&横向对比!$B22,【输出】数据汇总!$A:$A,0),MATCH(横向对比!$B$4,【输出】数据汇总!$1:$1,0)),"") -> 0.0179
B23: 关注贷款率 | C23: =IFERROR(INDEX(【输出】数据汇总!$A:$AZ,MATCH(横向对比!C$4&横向对比!$B23,【输出】数据汇总!$A:$A,0),MATCH(横向对比!$B$4,【输出】数据汇总!$1:$1,0)),"") -> 0.016283089 | D23: =IFERROR(INDEX(【输出】数据汇总!$A:$AZ,MATCH(横向对比!D$4&横向对比!$B23,【输出】数据汇总!$A:$A,0),MATCH(横向对比!$B$4,【输出】数据汇总!$1:$1,0)),"") -> 0.016333851 | E23: =IFERROR(INDEX(【输出】数据汇总!$A:$AZ,MATCH(横向对比!E$4&横向对比!$B23,【输出】数据汇总!$A:$A,0),MATCH(横向对比!$B$4,【输出】数据汇总!$1:$1,0)),"") -> 0.020224906 | F23: =IFERROR(INDEX(【输出】数据汇总!$A:$AZ,MATCH(横向对比!F$4&横向对比!$B23,【输出】数据汇总!$A:$A,0),MATCH(横向对比!$B$4,【输出】数据汇总!$1:$1,0)),"") -> 0.01506918 | G23: =IFERROR(INDEX(【输出】数据汇总!$A:$AZ,MATCH(横向对比!G$4&横向对比!$B23,【输出】数据汇总!$A:$A,0),MATCH(横向对比!$B$4,【输出】数据汇总!$1:$1,0)),"") -> 0.013504419 | H23: =IFERROR(INDEX(【输出】数据汇总!$A:$AZ,MATCH(横向对比!H$4&横向对比!$B23,【输出】数据汇总!$A:$A,0),MATCH(横向对比!$B$4,【输出】数据汇总!$1:$1,0)),"") | I23: =IFERROR(INDEX(【输出】数据汇总!$A:$AZ,MATCH(横向对比!I$4&横向对比!$B23,【输出】数据汇总!$A:$A,0),MATCH(横向对比!$B$4,【输出】数据汇总!$1:$1,0)),"") -> 0.031361884 | J23: =IFERROR(INDEX(【输出】数据汇总!$A:$AZ,MATCH(横向对比!J$4&横向对比!$B23,【输出】数据汇总!$A:$A,0),MATCH(横向对比!$B$4,【输出】数据汇总!$1:$1,0)),"") -> 0.01949301 | ... BL23: =IFERROR(INDEX(【输出】数据汇总!$A:$AZ,MATCH(横向对比!BL$4&横向对比!$B23,【输出】数据汇总!$A:$A,0),MATCH(横向对比!$B$4,【输出】数据汇总!$1:$1,0)),"") -> 0.021318769
B24: 逾期+重组率 | C24: =IFERROR(C20+C21,"") -> 0.019839203 | D24: =IFERROR(D20+D21,"") -> 0.018684553 | E24: =IFERROR(E20+E21,"") -> 0.023846209 | F24: =IFERROR(F20+F21,"") -> 0.018434193 | G24: =IFERROR(G20+G21,"") -> 0.018391857 | H24: =IFERROR(H20+H21,"") | I24: =IFERROR(I20+I21,"") -> 0.042759775 | J24: =IFERROR(J20+J21,"") -> 0.020283213 | ... BL24: =IFERROR(BL20+BL21,"") -> 0.025331839
B25: 不良+关注率 | C25: =IFERROR(C22+C23,"") -> 0.027988645 | D25: =IFERROR(D22+D23,"") -> 0.028583851 | E25: =IFERROR(E22+E23,"") -> 0.032613795 | F25: =IFERROR(F22+F23,"") -> 0.027802514 | G25: =IFERROR(G22+G23,"") -> 0.022954419 | H25: =IFERROR(H22+H23,"") | I25: =IFERROR(I22+I23,"") -> 0.048954192 | J25: =IFERROR(J22+J23,"") -> 0.03259301 | ... BL25: =IFERROR(BL22+BL23,"") -> 0.039218769
A26: ⑥/① | B26: 广义风险贷款比率 | C26: =IFERROR(INDEX(【输出】数据汇总!$A:$AZ,MATCH(横向对比!C$4&横向对比!$B26,【输出】数据汇总!$A:$A,0),MATCH(横向对比!$B$4,【输出】数据汇总!$1:$1,0)),"") -> 0.027994659 | D26: =IFERROR(INDEX(【输出】数据汇总!$A:$AZ,MATCH(横向对比!D$4&横向对比!$B26,【输出】数据汇总!$A:$A,0),MATCH(横向对比!$B$4,【输出】数据汇总!$1:$1,0)),"") -> 0.028583851 | E26: =IFERROR(INDEX(【输出】数据汇总!$A:$AZ,MATCH(横向对比!E$4&横向对比!$B26,【输出】数据汇总!$A:$A,0),MATCH(横向对比!$B$4,【输出】数据汇总!$1:$1,0)),"") -> 0.032637853 | F26: =IFERROR(INDEX(【输出】数据汇总!$A:$AZ,MATCH(横向对比!F$4&横向对比!$B26,【输出】数据汇总!$A:$A,0),MATCH(横向对比!$B$4,【输出】数据汇总!$1:$1,0)),"") -> 0.027802514 | G26: =IFERROR(INDEX(【输出】数据汇总!$A:$AZ,MATCH(横向对比!G$4&横向对比!$B26,【输出】数据汇总!$A:$A,0),MATCH(横向对比!$B$4,【输出】数据汇总!$1:$1,0)),"") -> 0.022954419 | H26: =IFERROR(INDEX(【输出】数据汇总!$A:$AZ,MATCH(横向对比!H$4&横向对比!$B26,【输出】数据汇总!$A:$A,0),MATCH(横向对比!$B$4,【输出】数据汇总!$1:$1,0)),"") | I26: =IFERROR(INDEX(【输出】数据汇总!$A:$AZ,MATCH(横向对比!I$4&横向对比!$B26,【输出】数据汇总!$A:$A,0),MATCH(横向对比!$B$4,【输出】数据汇总!$1:$1,0)),"") -> 0.059157771 | J26: =IFERROR(INDEX(【输出】数据汇总!$A:$AZ,MATCH(横向对比!J$4&横向对比!$B26,【输出】数据汇总!$A:$A,0),MATCH(横向对比!$B$4,【输出】数据汇总!$1:$1,0)),"") -> 0.03259301 | ... BL26: =IFERROR(INDEX(【输出】数据汇总!$A:$AZ,MATCH(横向对比!BL$4&横向对比!$B26,【输出】数据汇总!$A:$A,0),MATCH(横向对比!$B$4,【输出】数据汇总!$1:$1,0)),"") -> 0.039218769
B27: 广义不良资产率 | C27: =IFERROR(INDEX(【输出】数据汇总!$A:$AZ,MATCH(横向对比!C$4&横向对比!$B27,【输出】数据汇总!$A:$A,0),MATCH(横向对比!$B$4,【输出】数据汇总!$1:$1,0)),"") -> 0.020501883 | D27: =IFERROR(INDEX(【输出】数据汇总!$A:$AZ,MATCH(横向对比!D$4&横向对比!$B27,【输出】数据汇总!$A:$A,0),MATCH(横向对比!$B$4,【输出】数据汇总!$1:$1,0)),"") -> 0.018134305 | E27: =IFERROR(INDEX(【输出】数据汇总!$A:$AZ,MATCH(横向对比!E$4&横向对比!$B27,【输出】数据汇总!$A:$A,0),MATCH(横向对比!$B$4,【输出】数据汇总!$1:$1,0)),"") -> 0.024301325 | F27: =IFERROR(INDEX(【输出】数据汇总!$A:$AZ,MATCH(横向对比!F$4&横向对比!$B27,【输出】数据汇总!$A:$A,0),MATCH(横向对比!$B$4,【输出】数据汇总!$1:$1,0)),"") -> 0.024956978 | G27: =IFERROR(INDEX(【输出】数据汇总!$A:$AZ,MATCH(横向对比!G$4&横向对比!$B27,【输出】数据汇总!$A:$A,0),MATCH(横向对比!$B$4,【输出】数据汇总!$1:$1,0)),"") -> 0.014614924 | H27: =IFERROR(INDEX(【输出】数据汇总!$A:$AZ,MATCH(横向对比!H$4&横向对比!$B27,【输出】数据汇总!$A:$A,0),MATCH(横向对比!$B$4,【输出】数据汇总!$1:$1,0)),"") | I27: =IFERROR(INDEX(【输出】数据汇总!$A:$AZ,MATCH(横向对比!I$4&横向对比!$B27,【输出】数据汇总!$A:$A,0),MATCH(横向对比!$B$4,【输出】数据汇总!$1:$1,0)),"") -> 0.040573345 | J27: =IFERROR(INDEX(【输出】数据汇总!$A:$AZ,MATCH(横向对比!J$4&横向对比!$B27,【输出】数据汇总!$A:$A,0),MATCH(横向对比!$B$4,【输出】数据汇总!$1:$1,0)),"") -> 0.020277644 | ... BL27: =IFERROR(INDEX(【输出】数据汇总!$A:$AZ,MATCH(横向对比!BL$4&横向对比!$B27,【输出】数据汇总!$A:$A,0),MATCH(横向对比!$B$4,【输出】数据汇总!$1:$1,0)),"") -> 0.021182164
B28: 拨备覆盖率 | C28: =IFERROR(INDEX(【输出】数据汇总!$A:$AZ,MATCH(横向对比!C$4&横向对比!$B28,【输出】数据汇总!$A:$A,0),MATCH(横向对比!$B$4,【输出】数据汇总!$1:$1,0)),"") -> 2.5897146 | D28: =IFERROR(INDEX(【输出】数据汇总!$A:$AZ,MATCH(横向对比!D$4&横向对比!$B28,【输出】数据汇总!$A:$A,0),MATCH(横向对比!$B$4,【输出】数据汇总!$1:$1,0)),"") -> 2.2933167 | E28: =IFERROR(INDEX(【输出】数据汇总!$A:$AZ,MATCH(横向对比!E$4&横向对比!$B28,【输出】数据汇总!$A:$A,0),MATCH(横向对比!$B$4,【输出】数据汇总!$1:$1,0)),"") -> 2.0593667 | F28: =IFERROR(INDEX(【输出】数据汇总!$A:$AZ,MATCH(横向对比!F$4&横向对比!$B28,【输出】数据汇总!$A:$A,0),MATCH(横向对比!$B$4,【输出】数据汇总!$1:$1,0)),"") -> 2.4123 | G28: =IFERROR(INDEX(【输出】数据汇总!$A:$AZ,MATCH(横向对比!G$4&横向对比!$B28,【输出】数据汇总!$A:$A,0),MATCH(横向对比!$B$4,【输出】数据汇总!$1:$1,0)),"") -> 3.593875 | H28: =IFERROR(INDEX(【输出】数据汇总!$A:$AZ,MATCH(横向对比!H$4&横向对比!$B28,【输出】数据汇总!$A:$A,0),MATCH(横向对比!$B$4,【输出】数据汇总!$1:$1,0)),"") | I28: =IFERROR(INDEX(【输出】数据汇总!$A:$AZ,MATCH(横向对比!I$4&横向对比!$B28,【输出】数据汇总!$A:$A,0),MATCH(横向对比!$B$4,【输出】数据汇总!$1:$1,0)),"") -> 2.1033154 | J28: =IFERROR(INDEX(【输出】数据汇总!$A:$AZ,MATCH(横向对比!J$4&横向对比!$B28,【输出】数据汇总!$A:$A,0),MATCH(横向对比!$B$4,【输出】数据汇总!$1:$1,0)),"") -> 2.136 | ... BL28: =IFERROR(INDEX(【输出】数据汇总!$A:$AZ,MATCH(横向对比!BL$4&横向对比!$B28,【输出】数据汇总!$A:$A,0),MATCH(横向对比!$B$4,【输出】数据汇总!$1:$1,0)),"") -> 2.0768
B29: 超额拨备/归母净利润(TTM) | C29: =C17/C18 -> -0.01863019 | D29: =D17/D18 -> 0.1571079 | E29: =E17/E18 -> -0.37475971 | F29: =F17/F18 -> #VALUE! | G29: =G17/G18 -> #VALUE! | H29: =H17/H18 -> #VALUE! | I29: =I17/I18 -> -1.7925527 | J29: =IFERROR(INDEX(【输出】数据汇总!$A:$AZ,MATCH(横向对比!J$4&横向对比!$B29,【输出】数据汇总!$A:$A,0),MATCH(横向对比!$B$4,【输出】数据汇总!$1:$1,0)),"") -> -0.12911829 | K29: =IFERROR(INDEX(【输出】数据汇总!$A:$AZ,MATCH(横向对比!K$4&横向对比!$B29,【输出】数据汇总!$A:$A,0),MATCH(横向对比!$B$4,【输出】数据汇总!$1:$1,0)),"") -> 0.052445121 | L29: =IFERROR(INDEX(【输出】数据汇总!$A:$AZ,MATCH(横向对比!L$4&横向对比!$B29,【输出】数据汇总!$A:$A,0),MATCH(横向对比!$B$4,【输出】数据汇总!$1:$1,0)),"") -> 1.0776063 | M29: =IFERROR(INDEX(【输出】数据汇总!$A:$AZ,MATCH(横向对比!M$4&横向对比!$B29,【输出】数据汇总!$A:$A,0),MATCH(横向对比!$B$4,【输出】数据汇总!$1:$1,0)),"") -> -0.096310287 | N29: =IFERROR(INDEX(【输出】数据汇总!$A:$AZ,MATCH(横向对比!N$4&横向对比!$B29,【输出】数据汇总!$A:$A,0),MATCH(横向对比!$B$4,【输出】数据汇总!$1:$1,0)),"") -> -0.27094872 | O29: =IFERROR(INDEX(【输出】数据汇总!$A:$AZ,MATCH(横向对比!O$4&横向对比!$B29,【输出】数据汇总!$A:$A,0),MATCH(横向对比!$B$4,【输出】数据汇总!$1:$1,0)),"") -> -0.14999382 | P29: =IFERROR(INDEX(【输出】数据汇总!$A:$AZ,MATCH(横向对比!P$4&横向对比!$B29,【输出】数据汇总!$A:$A,0),MATCH(横向对比!$B$4,【输出】数据汇总!$1:$1,0)),"") -> 0.81879369 | Q29: =IFERROR(INDEX(【输出】数据汇总!$A:$AZ,MATCH(横向对比!Q$4&横向对比!$B29,【输出】数据汇总!$A:$A,0),MATCH(横向对比!$B$4,【输出】数据汇总!$1:$1,0)),"") -> -0.12770954 | ... BL29: =IFERROR(INDEX(【输出】数据汇总!$A:$AZ,MATCH(横向对比!BL$4&横向对比!$B29,【输出】数据汇总!$A:$A,0),MATCH(横向对比!$B$4,【输出】数据汇总!$1:$1,0)),"") -> -0.10942657
B30: 超额拨备/归母净资产 | C30: =C17/C19 -> -0.0015833041 | D30: =D17/D19 -> 0.013451455 | E30: =E17/E19 -> -0.029937332 | F30: =F17/F19 -> #VALUE! | G30: =G17/G19 -> #VALUE! | H30: =H17/H19 -> #VALUE! | I30: =I17/I19 -> -0.096618781 | J30: =IFERROR(INDEX(【输出】数据汇总!$A:$AZ,MATCH(横向对比!J$4&横向对比!$B30,【输出】数据汇总!$A:$A,0),MATCH(横向对比!$B$4,【输出】数据汇总!$1:$1,0)),"") -> -0.011212344 | K30: =IFERROR(INDEX(【输出】数据汇总!$A:$AZ,MATCH(横向对比!K$4&横向对比!$B30,【输出】数据汇总!$A:$A,0),MATCH(横向对比!$B$4,【输出】数据汇总!$1:$1,0)),"") -> 0.0048517533 | L30: =IFERROR(INDEX(【输出】数据汇总!$A:$AZ,MATCH(横向对比!L$4&横向对比!$B30,【输出】数据汇总!$A:$A,0),MATCH(横向对比!$B$4,【输出】数据汇总!$1:$1,0)),"") -> 0.096882909 | M30: =IFERROR(INDEX(【输出】数据汇总!$A:$AZ,MATCH(横向对比!M$4&横向对比!$B30,【输出】数据汇总!$A:$A,0),MATCH(横向对比!$B$4,【输出】数据汇总!$1:$1,0)),"") -> -0.0076387357 | N30: =IFERROR(INDEX(【输出】数据汇总!$A:$AZ,MATCH(横向对比!N$4&横向对比!$B30,【输出】数据汇总!$A:$A,0),MATCH(横向对比!$B$4,【输出】数据汇总!$1:$1,0)),"") -> -0.02041295 | O30: =IFERROR(INDEX(【输出】数据汇总!$A:$AZ,MATCH(横向对比!O$4&横向对比!$B30,【输出】数据汇总!$A:$A,0),MATCH(横向对比!$B$4,【输出】数据汇总!$1:$1,0)),"") -> -0.011300305 | P30: =IFERROR(INDEX(【输出】数据汇总!$A:$AZ,MATCH(横向对比!P$4&横向对比!$B30,【输出】数据汇总!$A:$A,0),MATCH(横向对比!$B$4,【输出】数据汇总!$1:$1,0)),"") -> 0.096605916 | Q30: =IFERROR(INDEX(【输出】数据汇总!$A:$AZ,MATCH(横向对比!Q$4&横向对比!$B30,【输出】数据汇总!$A:$A,0),MATCH(横向对比!$B$4,【输出】数据汇总!$1:$1,0)),"") -> -0.010971892 | ... BL30: =IFERROR(INDEX(【输出】数据汇总!$A:$AZ,MATCH(横向对比!BL$4&横向对比!$B30,【输出】数据汇总!$A:$A,0),MATCH(横向对比!$B$4,【输出】数据汇总!$1:$1,0)),"") -> -0.0069942954
B31: 归母净利润增速(TTM) | C31: =IFERROR(INDEX(【输出】数据汇总!$A:$AZ,MATCH(横向对比!C$4&横向对比!$B31,【输出】数据汇总!$A:$A,0),MATCH(横向对比!$B$4,【输出】数据汇总!$1:$1,0)),"") -> -0.0013858927 | D31: =IFERROR(INDEX(【输出】数据汇总!$A:$AZ,MATCH(横向对比!D$4&横向对比!$B31,【输出】数据汇总!$A:$A,0),MATCH(横向对比!$B$4,【输出】数据汇总!$1:$1,0)),"") -> 0.017214133 | E31: =IFERROR(INDEX(【输出】数据汇总!$A:$AZ,MATCH(横向对比!E$4&横向对比!$B31,【输出】数据汇总!$A:$A,0),MATCH(横向对比!$B$4,【输出】数据汇总!$1:$1,0)),"") -> -0.019985919 | F31: =IFERROR(INDEX(【输出】数据汇总!$A:$AZ,MATCH(横向对比!F$4&横向对比!$B31,【输出】数据汇总!$A:$A,0),MATCH(横向对比!$B$4,【输出】数据汇总!$1:$1,0)),"") | G31: =IFERROR(INDEX(【输出】数据汇总!$A:$AZ,MATCH(横向对比!G$4&横向对比!$B31,【输出】数据汇总!$A:$A,0),MATCH(横向对比!$B$4,【输出】数据汇总!$1:$1,0)),"") | H31: =IFERROR(INDEX(【输出】数据汇总!$A:$AZ,MATCH(横向对比!H$4&横向对比!$B31,【输出】数据汇总!$A:$A,0),MATCH(横向对比!$B$4,【输出】数据汇总!$1:$1,0)),"") | I31: =IFERROR(INDEX(【输出】数据汇总!$A:$AZ,MATCH(横向对比!I$4&横向对比!$B31,【输出】数据汇总!$A:$A,0),MATCH(横向对比!$B$4,【输出】数据汇总!$1:$1,0)),"") -> 0.042303814 | J31: =IFERROR(INDEX(【输出】数据汇总!$A:$AZ,MATCH(横向对比!J$4&横向对比!$B31,【输出】数据汇总!$A:$A,0),MATCH(横向对比!$B$4,【输出】数据汇总!$1:$1,0)),"") -> 0.0073770783 | ... BL31: =IFERROR(INDEX(【输出】数据汇总!$A:$AZ,MATCH(横向对比!BL$4&横向对比!$B31,【输出】数据汇总!$A:$A,0),MATCH(横向对比!$B$4,【输出】数据汇总!$1:$1,0)),"") -> -0.16665953
B34: 45838 | C34: 上市银行 | D34: 国有行 | E34: 股份行 | F34: 城商行 | G34: 农商行 | H34: AH股 | I34: 纯H股 | J34: 国有1 | K34: 国有2 | L34: 国有3 | M34: 国有4 | N34: 国有5 | O34: 国有6 | P34: 股份1 | Q34: 股份2 | R34: 股份3 | S34: 股份4 | T34: 股份5 | U34: 股份6 | V34: 股份7 | W34: 股份8 | X34: 股份9 | Y34: 城商1 | Z34: 城商2 | AA34: 城商3 | AB34: 城商4 | AC34: 城商5 | AD34: 城商6 | AE34: 城商7 | AF34: 城商8 | AG34: 城商9 | AH34: 城商10 | AI34: 城商11 | AJ34: 城商12 | AK34: 城商13 | AL34: 城商14 | AM34: 城商15 | AN34: 城商16 | AO34: 城商17 | AP34: 农商1 | AQ34: 农商2 | AR34: 农商3 | AS34: 农商4 | AT34: 农商5 | AU34: 农商6 | AV34: 农商7 | AW34: 农商8 | AX34: 农商9 | AY34: 农商10 | AZ34: =AZ2 -> 纯H股1 | BA34: =BA2 -> 纯H股2 | BB34: =BB2 -> 纯H股3 | BC34: =BC2 -> 纯H股4 | BD34: =BD2 -> 纯H股5 | BE34: =BE2 -> 纯H股6 | BF34: =BF2 -> 纯H股7 | BG34: =BG2 -> 纯H股8 | ... BL34: =BL2 -> 纯H股13
B35: 单位：亿元 | J35: 1国有 | K35: 1国有 | L35: 1国有 | M35: 1国有 | N35: 1国有 | O35: 1国有 | P35: 2股份 | Q35: 2股份 | R35: 2股份 | S35: 2股份 | T35: 2股份 | U35: 2股份 | V35: 2股份 | W35: 2股份 | X35: 2股份 | Y35: 3城商 | Z35: 3城商 | AA35: 3城商 | AB35: 3城商 | AC35: 3城商 | AD35: 3城商 | AE35: 3城商 | AF35: 3城商 | AG35: 3城商 | AH35: 3城商 | AI35: 3城商 | AJ35: 3城商 | AK35: 3城商 | AL35: 3城商 | AM35: 3城商 | AN35: 3城商 | AO35: 3城商 | AP35: 4农商 | AQ35: 4农商 | AR35: 4农商 | AS35: 4农商 | AT35: 4农商 | AU35: 4农商 | AV35: 4农商 | AW35: 4农商 | AX35: 4农商 | AY35: 4农商
B36: =B34 -> 45838 | C36: 上市银行 | D36: 国有行 | E36: 股份行 | F36: 城商行 | G36: 农商行 | H36: =H34 -> AH股 | I36: =I34 -> 纯H股 | J36: 工商 | K36: 建设 | L36: 农业 | M36: 中国 | N36: 邮储 | O36: 交通 | P36: 招商 | Q36: 兴业 | R36: 浦发 | S36: 中信 | T36: 民生 | U36: 光大 | V36: 平安 | W36: 华夏 | X36: 浙商 | Y36: 北京 | Z36: 江苏 | AA36: 上海 | AB36: 宁波 | AC36: 南京 | AD36: 杭州 | AE36: 成都 | AF36: 长沙 | AG36: 重庆 | AH36: 贵阳 | AI36: 郑州 | AJ36: 苏州 | AK36: 青岛 | AL36: 齐鲁 | AM36: 兰州 | AN36: 西安 | AO36: 厦门 | AP36: 渝农 | AQ36: 沪农 | AR36: 青农 | AS36: 常熟 | AT36: 紫金 | AU36: 无锡 | AV36: 张家港 | AW36: 苏农 | AX36: 瑞丰 | AY36: 江阴 | AZ36: 中原 | BA36: 广州农商 | BB36: 天津 | BC36: 江西 | BD36: 泸州 | BE36: 甘肃 | BF36: 晋商 | BG36: 徽商 | BH36: 哈尔滨 | BI36: 贵州 | BJ36: 渤海 | BK36: 威海 | BL36: 东莞农商
A37: ① | B37: 贷款总额 | C37: =IFERROR(INDEX(【输出】数据汇总!$A:$AZ,MATCH(横向对比!C$4&横向对比!$B37,【输出】数据汇总!$A:$A,0),MATCH(横向对比!$B$36,【输出】数据汇总!$1:$1,0))/100,"") -> 1844280.6 | D37: =IFERROR(INDEX(【输出】数据汇总!$A:$AZ,MATCH(横向对比!D$4&横向对比!$B37,【输出】数据汇总!$A:$A,0),MATCH(横向对比!$B$36,【输出】数据汇总!$1:$1,0))/100,"") -> 1258479.1 | E37: =IFERROR(INDEX(【输出】数据汇总!$A:$AZ,MATCH(横向对比!E$4&横向对比!$B37,【输出】数据汇总!$A:$A,0),MATCH(横向对比!$B$36,【输出】数据汇总!$1:$1,0))/100,"") -> 407161.05 | F37: =IFERROR(INDEX(【输出】数据汇总!$A:$AZ,MATCH(横向对比!F$4&横向对比!$B37,【输出】数据汇总!$A:$A,0),MATCH(横向对比!$B$36,【输出】数据汇总!$1:$1,0))/100,"") -> 148935.56 | G37: =IFERROR(INDEX(【输出】数据汇总!$A:$AZ,MATCH(横向对比!G$4&横向对比!$B37,【输出】数据汇总!$A:$A,0),MATCH(横向对比!$B$36,【输出】数据汇总!$1:$1,0))/100,"") -> 29704.89 | H37: =IFERROR(INDEX(【输出】数据汇总!$A:$AZ,MATCH(横向对比!H$4&横向对比!$B37,【输出】数据汇总!$A:$A,0),MATCH(横向对比!$B$36,【输出】数据汇总!$1:$1,0))/100,"") | I37: =IFERROR(INDEX(【输出】数据汇总!$A:$AZ,MATCH(横向对比!I$4&横向对比!$B37,【输出】数据汇总!$A:$A,0),MATCH(横向对比!$B$36,【输出】数据汇总!$1:$1,0))/100,"") -> 62830.955 | J37: =IFERROR(INDEX(【输出】数据汇总!$A:$AZ,MATCH(横向对比!J$4&横向对比!$B37,【输出】数据汇总!$A:$A,0),MATCH(横向对比!$B$36,【输出】数据汇总!$1:$1,0))/100,"") -> 301856.59 | ... AA37: =IFERROR(INDEX(【输出】数据汇总!$A:$AZ,MATCH(横向对比!AA$4&横向对比!$B37,【输出】数据汇总!$A:$A,0),MATCH(横向对比!$B$36,【输出】数据汇总!$1:$1,0))/100,"") -> 14369.837 | AB37: =IFERROR(INDEX(【输出】数据汇总!$A:$AZ,MATCH(横向对比!AB$36&横向对比!$B37,【输出】数据汇总!$A:$A,0),MATCH(横向对比!$B$36,【输出】数据汇总!$1:$1,0))/100,"") -> 16732.13 | AC37: =IFERROR(INDEX(【输出】数据汇总!$A:$AZ,MATCH(横向对比!AC$4&横向对比!$B37,【输出】数据汇总!$A:$A,0),MATCH(横向对比!$B$36,【输出】数据汇总!$1:$1,0))/100,"") -> 13871.734 | AD37: =IFERROR(INDEX(【输出】数据汇总!$A:$AZ,MATCH(横向对比!AD$4&横向对比!$B37,【输出】数据汇总!$A:$A,0),MATCH(横向对比!$B$36,【输出】数据汇总!$1:$1,0))/100,"") -> 10094.182 | AE37: =IFERROR(INDEX(【输出】数据汇总!$A:$AZ,MATCH(横向对比!AE$4&横向对比!$B37,【输出】数据汇总!$A:$A,0),MATCH(横向对比!$B$36,【输出】数据汇总!$1:$1,0))/100,"") -> 8334.1516 | AF37: =IFERROR(INDEX(【输出】数据汇总!$A:$AZ,MATCH(横向对比!AF$4&横向对比!$B37,【输出】数据汇总!$A:$A,0),MATCH(横向对比!$B$36,【输出】数据汇总!$1:$1,0))/100,"") -> 6026.9159 | AG37: =IFERROR(INDEX(【输出】数据汇总!$A:$AZ,MATCH(横向对比!AG$4&横向对比!$B37,【输出】数据汇总!$A:$A,0),MATCH(横向对比!$B$36,【输出】数据汇总!$1:$1,0))/100,"") -> 4986.4508 | AH37: =IFERROR(INDEX(【输出】数据汇总!$A:$AZ,MATCH(横向对比!AH$4&横向对比!$B37,【输出】数据汇总!$A:$A,0),MATCH(横向对比!$B$36,【输出】数据汇总!$1:$1,0))/100,"") -> 3434.6104 | AI37: =IFERROR(INDEX(【输出】数据汇总!$A:$AZ,MATCH(横向对比!AI$4&横向对比!$B37,【输出】数据汇总!$A:$A,0),MATCH(横向对比!$B$36,【输出】数据汇总!$1:$1,0))/100,"") -> 4060.9446 | AJ37: =IFERROR(INDEX(【输出】数据汇总!$A:$AZ,MATCH(横向对比!AJ$4&横向对比!$B37,【输出】数据汇总!$A:$A,0),MATCH(横向对比!$B$36,【输出】数据汇总!$1:$1,0))/100,"") -> 3634.9715 | ... BA37: =IFERROR(INDEX(【输出】数据汇总!$A:$AZ,MATCH(横向对比!BA$4&横向对比!$B37,【输出】数据汇总!$A:$A,0),MATCH(横向对比!$B$36,【输出】数据汇总!$1:$1,0))/100,"") -> 7173.4444 | BB37: =IFERROR(INDEX(【输出】数据汇总!$A:$AZ,MATCH(横向对比!BB$36&横向对比!$B37,【输出】数据汇总!$A:$A,0),MATCH(横向对比!$B$36,【输出】数据汇总!$1:$1,0))/100,"") -> 4849.6898 | BC37: =IFERROR(INDEX(【输出】数据汇总!$A:$AZ,MATCH(横向对比!BC$4&横向对比!$B37,【输出】数据汇总!$A:$A,0),MATCH(横向对比!$B$36,【输出】数据汇总!$1:$1,0))/100,"") -> 3649.0307 | BD37: =IFERROR(INDEX(【输出】数据汇总!$A:$AZ,MATCH(横向对比!BD$4&横向对比!$B37,【输出】数据汇总!$A:$A,0),MATCH(横向对比!$B$36,【输出】数据汇总!$1:$1,0))/100,"") -> 1168.2949 | BE37: =IFERROR(INDEX(【输出】数据汇总!$A:$AZ,MATCH(横向对比!BE$4&横向对比!$B37,【输出】数据汇总!$A:$A,0),MATCH(横向对比!$B$36,【输出】数据汇总!$1:$1,0))/100,"") -> 2348.2905 | BF37: =IFERROR(INDEX(【输出】数据汇总!$A:$AZ,MATCH(横向对比!BF$4&横向对比!$B37,【输出】数据汇总!$A:$A,0),MATCH(横向对比!$B$36,【输出】数据汇总!$1:$1,0))/100,"") -> 2086.3832 | BG37: =IFERROR(INDEX(【输出】数据汇总!$A:$AZ,MATCH(横向对比!BG$4&横向对比!$B37,【输出】数据汇总!$A:$A,0),MATCH(横向对比!$B$36,【输出】数据汇总!$1:$1,0))/100,"") -> 11005.329 | BH37: =IFERROR(INDEX(【输出】数据汇总!$A:$AZ,MATCH(横向对比!BH$4&横向对比!$B37,【输出】数据汇总!$A:$A,0),MATCH(横向对比!$B$36,【输出】数据汇总!$1:$1,0))/100,"") -> 3975.6626 | BI37: =IFERROR(INDEX(【输出】数据汇总!$A:$AZ,MATCH(横向对比!BI$4&横向对比!$B37,【输出】数据汇总!$A:$A,0),MATCH(横向对比!$B$36,【输出】数据汇总!$1:$1,0))/100,"") -> 3643.4705 | BJ37: =IFERROR(INDEX(【输出】数据汇总!$A:$AZ,MATCH(横向对比!BJ$4&横向对比!$B37,【输出】数据汇总!$A:$A,0),MATCH(横向对比!$B$36,【输出】数据汇总!$1:$1,0))/100,"") -> 9544.2198 | ... BL37: =IFERROR(INDEX(【输出】数据汇总!$A:$AZ,MATCH(横向对比!BL$4&横向对比!$B37,【输出】数据汇总!$A:$A,0),MATCH(横向对比!$B$36,【输出】数据汇总!$1:$1,0))/100,"") -> 3944.1518
A38: ② | B38: 逾期贷款余额 | C38: =IFERROR(INDEX(【输出】数据汇总!$A:$AZ,MATCH(横向对比!C$4&横向对比!$B38,【输出】数据汇总!$A:$A,0),MATCH(横向对比!$B$36,【输出】数据汇总!$1:$1,0))/100,"") -> 26533.771 | D38: =IFERROR(INDEX(【输出】数据汇总!$A:$AZ,MATCH(横向对比!D$4&横向对比!$B38,【输出】数据汇总!$A:$A,0),MATCH(横向对比!$B$36,【输出】数据汇总!$1:$1,0))/100,"") -> 16945.3 | E38: =IFERROR(INDEX(【输出】数据汇总!$A:$AZ,MATCH(横向对比!E$4&横向对比!$B38,【输出】数据汇总!$A:$A,0),MATCH(横向对比!$B$36,【输出】数据汇总!$1:$1,0))/100,"") -> 6959.76 | F38: =IFERROR(INDEX(【输出】数据汇总!$A:$AZ,MATCH(横向对比!F$4&横向对比!$B38,【输出】数据汇总!$A:$A,0),MATCH(横向对比!$B$36,【输出】数据汇总!$1:$1,0))/100,"") -> 2169.1632 | G38: =IFERROR(INDEX(【输出】数据汇总!$A:$AZ,MATCH(横向对比!G$4&横向对比!$B38,【输出】数据汇总!$A:$A,0),MATCH(横向对比!$B$36,【输出】数据汇总!$1:$1,0))/100,"") -> 459.54783 | H38: =IFERROR(INDEX(【输出】数据汇总!$A:$AZ,MATCH(横向对比!H$4&横向对比!$B38,【输出】数据汇总!$A:$A,0),MATCH(横向对比!$B$36,【输出】数据汇总!$1:$1,0))/100,"") | I38: =IFERROR(INDEX(【输出】数据汇总!$A:$AZ,MATCH(横向对比!I$4&横向对比!$B38,【输出】数据汇总!$A:$A,0),MATCH(横向对比!$B$36,【输出】数据汇总!$1:$1,0))/100,"") -> 2356.8758 | J38: =IFERROR(INDEX(【输出】数据汇总!$A:$AZ,MATCH(横向对比!J$4&横向对比!$B38,【输出】数据汇总!$A:$A,0),MATCH(横向对比!$B$36,【输出】数据汇总!$1:$1,0))/100,"") -> 4590 | ... AA38: =IFERROR(INDEX(【输出】数据汇总!$A:$AZ,MATCH(横向对比!AA$4&横向对比!$B38,【输出】数据汇总!$A:$A,0),MATCH(横向对比!$B$36,【输出】数据汇总!$1:$1,0))/100,"") -> 229.32856 | AB38: =IFERROR(INDEX(【输出】数据汇总!$A:$AZ,MATCH(横向对比!AB$36&横向对比!$B38,【输出】数据汇总!$A:$A,0),MATCH(横向对比!$B$36,【输出】数据汇总!$1:$1,0))/100,"") -> 148.22 | AC38: =IFERROR(INDEX(【输出】数据汇总!$A:$AZ,MATCH(横向对比!AC$4&横向对比!$B38,【输出】数据汇总!$A:$A,0),MATCH(横向对比!$B$36,【输出】数据汇总!$1:$1,0))/100,"") -> 176.06707 | AD38: =IFERROR(INDEX(【输出】数据汇总!$A:$AZ,MATCH(横向对比!AD$4&横向对比!$B38,【输出】数据汇总!$A:$A,0),MATCH(横向对比!$B$36,【输出】数据汇总!$1:$1,0))/100,"") -> 61.22921 | AE38: =IFERROR(INDEX(【输出】数据汇总!$A:$AZ,MATCH(横向对比!AE$4&横向对比!$B38,【输出】数据汇总!$A:$A,0),MATCH(横向对比!$B$36,【输出】数据汇总!$1:$1,0))/100,"") -> 64.01745 | AF38: =IFERROR(INDEX(【输出】数据汇总!$A:$AZ,MATCH(横向对比!AF$4&横向对比!$B38,【输出】数据汇总!$A:$A,0),MATCH(横向对比!$B$36,【输出】数据汇总!$1:$1,0))/100,"") -> 134.04604 | AG38: =IFERROR(INDEX(【输出】数据汇总!$A:$AZ,MATCH(横向对比!AG$4&横向对比!$B38,【输出】数据汇总!$A:$A,0),MATCH(横向对比!$B$36,【输出】数据汇总!$1:$1,0))/100,"") -> 78.57164 | AH38: =IFERROR(INDEX(【输出】数据汇总!$A:$AZ,MATCH(横向对比!AH$4&横向对比!$B38,【输出】数据汇总!$A:$A,0),MATCH(横向对比!$B$36,【输出】数据汇总!$1:$1,0))/100,"") -> 97.28655 | AI38: =IFERROR(INDEX(【输出】数据汇总!$A:$AZ,MATCH(横向对比!AI$4&横向对比!$B38,【输出】数据汇总!$A:$A,0),MATCH(横向对比!$B$36,【输出】数据汇总!$1:$1,0))/100,"") -> 210.88098 | AJ38: =IFERROR(INDEX(【输出】数据汇总!$A:$AZ,MATCH(横向对比!AJ$4&横向对比!$B38,【输出】数据汇总!$A:$A,0),MATCH(横向对比!$B$36,【输出】数据汇总!$1:$1,0))/100,"") -> 35.90612 | ... BA38: =IFERROR(INDEX(【输出】数据汇总!$A:$AZ,MATCH(横向对比!BA$4&横向对比!$B38,【输出】数据汇总!$A:$A,0),MATCH(横向对比!$B$36,【输出】数据汇总!$1:$1,0))/100,"") -> 510.93051 | BB38: =IFERROR(INDEX(【输出】数据汇总!$A:$AZ,MATCH(横向对比!BB$36&横向对比!$B38,【输出】数据汇总!$A:$A,0),MATCH(横向对比!$B$36,【输出】数据汇总!$1:$1,0))/100,"") -> 128.33317 | BC38: =IFERROR(INDEX(【输出】数据汇总!$A:$AZ,MATCH(横向对比!BC$4&横向对比!$B38,【输出】数据汇总!$A:$A,0),MATCH(横向对比!$B$36,【输出】数据汇总!$1:$1,0))/100,"") -> 131.70501 | BD38: =IFERROR(INDEX(【输出】数据汇总!$A:$AZ,MATCH(横向对比!BD$4&横向对比!$B38,【输出】数据汇总!$A:$A,0),MATCH(横向对比!$B$36,【输出】数据汇总!$1:$1,0))/100,"") -> 17.88028 | BE38: =IFERROR(INDEX(【输出】数据汇总!$A:$AZ,MATCH(横向对比!BE$4&横向对比!$B38,【输出】数据汇总!$A:$A,0),MATCH(横向对比!$B$36,【输出】数据汇总!$1:$1,0))/100,"") -> 61.335 | BF38: =IFERROR(INDEX(【输出】数据汇总!$A:$AZ,MATCH(横向对比!BF$4&横向对比!$B38,【输出】数据汇总!$A:$A,0),MATCH(横向对比!$B$36,【输出】数据汇总!$1:$1,0))/100,"") -> 42.40352 | BG38: =IFERROR(INDEX(【输出】数据汇总!$A:$AZ,MATCH(横向对比!BG$4&横向对比!$B38,【输出】数据汇总!$A:$A,0),MATCH(横向对比!$B$36,【输出】数据汇总!$1:$1,0))/100,"") -> 133.46406 | BH38: =IFERROR(INDEX(【输出】数据汇总!$A:$AZ,MATCH(横向对比!BH$4&横向对比!$B38,【输出】数据汇总!$A:$A,0),MATCH(横向对比!$B$36,【输出】数据汇总!$1:$1,0))/100,"") -> 516.41793 | BI38: =IFERROR(INDEX(【输出】数据汇总!$A:$AZ,MATCH(横向对比!BI$4&横向对比!$B38,【输出】数据汇总!$A:$A,0),MATCH(横向对比!$B$36,【输出】数据汇总!$1:$1,0))/100,"") -> 101.22117 | BJ38: =IFERROR(INDEX(【输出】数据汇总!$A:$AZ,MATCH(横向对比!BJ$4&横向对比!$B38,【输出】数据汇总!$A:$A,0),MATCH(横向对比!$B$36,【输出】数据汇总!$1:$1,0))/100,"") -> 291.61037 | ... BL38: =IFERROR(INDEX(【输出】数据汇总!$A:$AZ,MATCH(横向对比!BL$4&横向对比!$B38,【输出】数据汇总!$A:$A,0),MATCH(横向对比!$B$36,【输出】数据汇总!$1:$1,0))/100,"") -> 94.75837
A39: ③ | B39: 重组贷款余额 | C39: =IFERROR(INDEX(【输出】数据汇总!$A:$AZ,MATCH(横向对比!C$4&横向对比!$B39,【输出】数据汇总!$A:$A,0),MATCH(横向对比!$B$36,【输出】数据汇总!$1:$1,0))/100,"") -> 9233.5316 | D39: =IFERROR(INDEX(【输出】数据汇总!$A:$AZ,MATCH(横向对比!D$4&横向对比!$B39,【输出】数据汇总!$A:$A,0),MATCH(横向对比!$B$36,【输出】数据汇总!$1:$1,0))/100,"") -> 5968.76 | E39: =IFERROR(INDEX(【输出】数据汇总!$A:$AZ,MATCH(横向对比!E$4&横向对比!$B39,【输出】数据汇总!$A:$A,0),MATCH(横向对比!$B$36,【输出】数据汇总!$1:$1,0))/100,"") -> 2417.65 | F39: =IFERROR(INDEX(【输出】数据汇总!$A:$AZ,MATCH(横向对比!F$4&横向对比!$B39,【输出】数据汇总!$A:$A,0),MATCH(横向对比!$B$36,【输出】数据汇总!$1:$1,0))/100,"") -> 654.5717 | G39: =IFERROR(INDEX(【输出】数据汇总!$A:$AZ,MATCH(横向对比!G$4&横向对比!$B39,【输出】数据汇总!$A:$A,0),MATCH(横向对比!$B$36,【输出】数据汇总!$1:$1,0))/100,"") -> 192.54987 | H39: =IFERROR(INDEX(【输出】数据汇总!$A:$AZ,MATCH(横向对比!H$4&横向对比!$B39,【输出】数据汇总!$A:$A,0),MATCH(横向对比!$B$36,【输出】数据汇总!$1:$1,0))/100,"") | I39: =IFERROR(INDEX(【输出】数据汇总!$A:$AZ,MATCH(横向对比!I$4&横向对比!$B39,【输出】数据汇总!$A:$A,0),MATCH(横向对比!$B$36,【输出】数据汇总!$1:$1,0))/100,"") -> 712.55198 | J39: =IFERROR(INDEX(【输出】数据汇总!$A:$AZ,MATCH(横向对比!J$4&横向对比!$B39,【输出】数据汇总!$A:$A,0),MATCH(横向对比!$B$36,【输出】数据汇总!$1:$1,0))/100,"") -> 1409.62 | ... AA39: =IFERROR(INDEX(【输出】数据汇总!$A:$AZ,MATCH(横向对比!AA$4&横向对比!$B39,【输出】数据汇总!$A:$A,0),MATCH(横向对比!$B$36,【输出】数据汇总!$1:$1,0))/100,"") -> 48.43716 | AB39: =IFERROR(INDEX(【输出】数据汇总!$A:$AZ,MATCH(横向对比!AB$36&横向对比!$B39,【输出】数据汇总!$A:$A,0),MATCH(横向对比!$B$36,【输出】数据汇总!$1:$1,0))/100,"") -> 39.44 | AC39: =IFERROR(INDEX(【输出】数据汇总!$A:$AZ,MATCH(横向对比!AC$4&横向对比!$B39,【输出】数据汇总!$A:$A,0),MATCH(横向对比!$B$36,【输出】数据汇总!$1:$1,0))/100,"") -> 82.38927 | AD39: =IFERROR(INDEX(【输出】数据汇总!$A:$AZ,MATCH(横向对比!AD$4&横向对比!$B39,【输出】数据汇总!$A:$A,0),MATCH(横向对比!$B$36,【输出】数据汇总!$1:$1,0))/100,"") -> 25.63984 | AE39: =IFERROR(INDEX(【输出】数据汇总!$A:$AZ,MATCH(横向对比!AE$4&横向对比!$B39,【输出】数据汇总!$A:$A,0),MATCH(横向对比!$B$36,【输出】数据汇总!$1:$1,0))/100,"") -> 19.44866 | AF39: =IFERROR(INDEX(【输出】数据汇总!$A:$AZ,MATCH(横向对比!AF$4&横向对比!$B39,【输出】数据汇总!$A:$A,0),MATCH(横向对比!$B$36,【输出】数据汇总!$1:$1,0))/100,"") -> 36.49396 | AG39: =IFERROR(INDEX(【输出】数据汇总!$A:$AZ,MATCH(横向对比!AG$4&横向对比!$B39,【输出】数据汇总!$A:$A,0),MATCH(横向对比!$B$36,【输出】数据汇总!$1:$1,0))/100,"") -> 10.04388 | AH39: =IFERROR(INDEX(【输出】数据汇总!$A:$AZ,MATCH(横向对比!AH$4&横向对比!$B39,【输出】数据汇总!$A:$A,0),MATCH(横向对比!$B$36,【输出】数据汇总!$1:$1,0))/100,"") -> 45.40678 | AI39: =IFERROR(INDEX(【输出】数据汇总!$A:$AZ,MATCH(横向对比!AI$4&横向对比!$B39,【输出】数据汇总!$A:$A,0),MATCH(横向对比!$B$36,【输出】数据汇总!$1:$1,0))/100,"") | AJ39: =IFERROR(INDEX(【输出】数据汇总!$A:$AZ,MATCH(横向对比!AJ$4&横向对比!$B39,【输出】数据汇总!$A:$A,0),MATCH(横向对比!$B$36,【输出】数据汇总!$1:$1,0))/100,"") -> 17.01193 | ... BA39: =IFERROR(INDEX(【输出】数据汇总!$A:$AZ,MATCH(横向对比!BA$4&横向对比!$B39,【输出】数据汇总!$A:$A,0),MATCH(横向对比!$B$36,【输出】数据汇总!$1:$1,0))/100,"") -> 336.81 | BB39: =IFERROR(INDEX(【输出】数据汇总!$A:$AZ,MATCH(横向对比!BB$36&横向对比!$B39,【输出】数据汇总!$A:$A,0),MATCH(横向对比!$B$36,【输出】数据汇总!$1:$1,0))/100,"") -> 0 | BC39: =IFERROR(INDEX(【输出】数据汇总!$A:$AZ,MATCH(横向对比!BC$4&横向对比!$B39,【输出】数据汇总!$A:$A,0),MATCH(横向对比!$B$36,【输出】数据汇总!$1:$1,0))/100,"") -> 0 | BD39: =IFERROR(INDEX(【输出】数据汇总!$A:$AZ,MATCH(横向对比!BD$4&横向对比!$B39,【输出】数据汇总!$A:$A,0),MATCH(横向对比!$B$36,【输出】数据汇总!$1:$1,0))/100,"") -> 3.41036 | BE39: =IFERROR(INDEX(【输出】数据汇总!$A:$AZ,MATCH(横向对比!BE$4&横向对比!$B39,【输出】数据汇总!$A:$A,0),MATCH(横向对比!$B$36,【输出】数据汇总!$1:$1,0))/100,"") -> 0 | BF39: =IFERROR(INDEX(【输出】数据汇总!$A:$AZ,MATCH(横向对比!BF$4&横向对比!$B39,【输出】数据汇总!$A:$A,0),MATCH(横向对比!$B$36,【输出】数据汇总!$1:$1,0))/100,"") -> 0 | BG39: =IFERROR(INDEX(【输出】数据汇总!$A:$AZ,MATCH(横向对比!BG$4&横向对比!$B39,【输出】数据汇总!$A:$A,0),MATCH(横向对比!$B$36,【输出】数据汇总!$1:$1,0))/100,"") -> 34.37 | BH39: =IFERROR(INDEX(【输出】数据汇总!$A:$AZ,MATCH(横向对比!BH$4&横向对比!$B39,【输出】数据汇总!$A:$A,0),MATCH(横向对比!$B$36,【输出】数据汇总!$1:$1,0))/100,"") -> 277.98 | BI39: =IFERROR(INDEX(【输出】数据汇总!$A:$AZ,MATCH(横向对比!BI$4&横向对比!$B39,【输出】数据汇总!$A:$A,0),MATCH(横向对比!$B$36,【输出】数据汇总!$1:$1,0))/100,"") -> 33.9851 | BJ39: =IFERROR(INDEX(【输出】数据汇总!$A:$AZ,MATCH(横向对比!BJ$4&横向对比!$B39,【输出】数据汇总!$A:$A,0),MATCH(横向对比!$B$36,【输出】数据汇总!$1:$1,0))/100,"") -> 17.139756 | ... BL39: =IFERROR(INDEX(【输出】数据汇总!$A:$AZ,MATCH(横向对比!BL$4&横向对比!$B39,【输出】数据汇总!$A:$A,0),MATCH(横向对比!$B$36,【输出】数据汇总!$1:$1,0))/100,"") -> 8.85676
A40: ④ | B40: 不良贷款余额 | C40: =IFERROR(INDEX(【输出】数据汇总!$A:$AZ,MATCH(横向对比!C$4&横向对比!$B40,【输出】数据汇总!$A:$A,0),MATCH(横向对比!$B$36,【输出】数据汇总!$1:$1,0))/100,"") -> 22664.333 | D40: =IFERROR(INDEX(【输出】数据汇总!$A:$AZ,MATCH(横向对比!D$4&横向对比!$B40,【输出】数据汇总!$A:$A,0),MATCH(横向对比!$B$36,【输出】数据汇总!$1:$1,0))/100,"") -> 15927.35 | E40: =IFERROR(INDEX(【输出】数据汇总!$A:$AZ,MATCH(横向对比!E$4&横向对比!$B40,【输出】数据汇总!$A:$A,0),MATCH(横向对比!$B$36,【输出】数据汇总!$1:$1,0))/100,"") -> 4877.2 | F40: =IFERROR(INDEX(【输出】数据汇总!$A:$AZ,MATCH(横向对比!F$4&横向对比!$B40,【输出】数据汇总!$A:$A,0),MATCH(横向对比!$B$36,【输出】数据汇总!$1:$1,0))/100,"") -> 1541.0244 | G40: =IFERROR(INDEX(【输出】数据汇总!$A:$AZ,MATCH(横向对比!G$4&横向对比!$B40,【输出】数据汇总!$A:$A,0),MATCH(横向对比!$B$36,【输出】数据汇总!$1:$1,0))/100,"") -> 318.75834 | H40: =IFERROR(INDEX(【输出】数据汇总!$A:$AZ,MATCH(横向对比!H$4&横向对比!$B40,【输出】数据汇总!$A:$A,0),MATCH(横向对比!$B$36,【输出】数据汇总!$1:$1,0))/100,"") | I40: =IFERROR(INDEX(【输出】数据汇总!$A:$AZ,MATCH(横向对比!I$4&横向对比!$B40,【输出】数据汇总!$A:$A,0),MATCH(横向对比!$B$36,【输出】数据汇总!$1:$1,0))/100,"") -> 1107.817 | J40: =IFERROR(INDEX(【输出】数据汇总!$A:$AZ,MATCH(横向对比!J$4&横向对比!$B40,【输出】数据汇总!$A:$A,0),MATCH(横向对比!$B$36,【输出】数据汇总!$1:$1,0))/100,"") -> 4001.05 | ... AA40: =IFERROR(INDEX(【输出】数据汇总!$A:$AZ,MATCH(横向对比!AA$4&横向对比!$B40,【输出】数据汇总!$A:$A,0),MATCH(横向对比!$B$36,【输出】数据汇总!$1:$1,0))/100,"") -> 169.3945 | AB40: =IFERROR(INDEX(【输出】数据汇总!$A:$AZ,MATCH(横向对比!AB$36&横向对比!$B40,【输出】数据汇总!$A:$A,0),MATCH(横向对比!$B$36,【输出】数据汇总!$1:$1,0))/100,"") -> 126.88 | AC40: =IFERROR(INDEX(【输出】数据汇总!$A:$AZ,MATCH(横向对比!AC$4&横向对比!$B40,【输出】数据汇总!$A:$A,0),MATCH(横向对比!$B$36,【输出】数据汇总!$1:$1,0))/100,"") -> 115.93837 | AD40: =IFERROR(INDEX(【输出】数据汇总!$A:$AZ,MATCH(横向对比!AD$4&横向对比!$B40,【输出】数据汇总!$A:$A,0),MATCH(横向对比!$B$36,【输出】数据汇总!$1:$1,0))/100,"") -> 76.59031 | AE40: =IFERROR(INDEX(【输出】数据汇总!$A:$AZ,MATCH(横向对比!AE$4&横向对比!$B40,【输出】数据汇总!$A:$A,0),MATCH(横向对比!$B$36,【输出】数据汇总!$1:$1,0))/100,"") -> 54.80575 | AF40: =IFERROR(INDEX(【输出】数据汇总!$A:$AZ,MATCH(横向对比!AF$4&横向对比!$B40,【输出】数据汇总!$A:$A,0),MATCH(横向对比!$B$36,【输出】数据汇总!$1:$1,0))/100,"") -> 70.46426 | AG40: =IFERROR(INDEX(【输出】数据汇总!$A:$AZ,MATCH(横向对比!AG$4&横向对比!$B40,【输出】数据汇总!$A:$A,0),MATCH(横向对比!$B$36,【输出】数据汇总!$1:$1,0))/100,"") -> 58.40237 | AH40: =IFERROR(INDEX(【输出】数据汇总!$A:$AZ,MATCH(横向对比!AH$4&横向对比!$B40,【输出】数据汇总!$A:$A,0),MATCH(横向对比!$B$36,【输出】数据汇总!$1:$1,0))/100,"") -> 58.2353 | AI40: =IFERROR(INDEX(【输出】数据汇总!$A:$AZ,MATCH(横向对比!AI$4&横向对比!$B40,【输出】数据汇总!$A:$A,0),MATCH(横向对比!$B$36,【输出】数据汇总!$1:$1,0))/100,"") -> 71.6505 | AJ40: =IFERROR(INDEX(【输出】数据汇总!$A:$AZ,MATCH(横向对比!AJ$4&横向对比!$B40,【输出】数据汇总!$A:$A,0),MATCH(横向对比!$B$36,【输出】数据汇总!$1:$1,0))/100,"") -> 30.11518 | ... BA40: =IFERROR(INDEX(【输出】数据汇总!$A:$AZ,MATCH(横向对比!BA$4&横向对比!$B40,【输出】数据汇总!$A:$A,0),MATCH(横向对比!$B$36,【输出】数据汇总!$1:$1,0))/100,"") -> 142.0342 | BB40: =IFERROR(INDEX(【输出】数据汇总!$A:$AZ,MATCH(横向对比!BB$36&横向对比!$B40,【输出】数据汇总!$A:$A,0),MATCH(横向对比!$B$36,【输出】数据汇总!$1:$1,0))/100,"") -> 81.474788 | BC40: =IFERROR(INDEX(【输出】数据汇总!$A:$AZ,MATCH(横向对比!BC$4&横向对比!$B40,【输出】数据汇总!$A:$A,0),MATCH(横向对比!$B$36,【输出】数据汇总!$1:$1,0))/100,"") -> 86.117125 | BD40: =IFERROR(INDEX(【输出】数据汇总!$A:$AZ,MATCH(横向对比!BD$4&横向对比!$B40,【输出】数据汇总!$A:$A,0),MATCH(横向对比!$B$36,【输出】数据汇总!$1:$1,0))/100,"") -> 13.78588 | BE40: =IFERROR(INDEX(【输出】数据汇总!$A:$AZ,MATCH(横向对比!BE$4&横向对比!$B40,【输出】数据汇总!$A:$A,0),MATCH(横向对比!$B$36,【输出】数据汇总!$1:$1,0))/100,"") -> 43.443374 | BF40: =IFERROR(INDEX(【输出】数据汇总!$A:$AZ,MATCH(横向对比!BF$4&横向对比!$B40,【输出】数据汇总!$A:$A,0),MATCH(横向对比!$B$36,【输出】数据汇总!$1:$1,0))/100,"") -> 36.928983 | BG40: =IFERROR(INDEX(【输出】数据汇总!$A:$AZ,MATCH(横向对比!BG$4&横向对比!$B40,【输出】数据汇总!$A:$A,0),MATCH(横向对比!$B$36,【输出】数据汇总!$1:$1,0))/100,"") -> 107.85223 | BH40: =IFERROR(INDEX(【输出】数据汇总!$A:$AZ,MATCH(横向对比!BH$4&横向对比!$B40,【输出】数据汇总!$A:$A,0),MATCH(横向对比!$B$36,【输出】数据汇总!$1:$1,0))/100,"") -> 112.51125 | BI40: =IFERROR(INDEX(【输出】数据汇总!$A:$AZ,MATCH(横向对比!BI$4&横向对比!$B40,【输出】数据汇总!$A:$A,0),MATCH(横向对比!$B$36,【输出】数据汇总!$1:$1,0))/100,"") -> 61.574652 | BJ40: =IFERROR(INDEX(【输出】数据汇总!$A:$AZ,MATCH(横向对比!BJ$4&横向对比!$B40,【输出】数据汇总!$A:$A,0),MATCH(横向对比!$B$36,【输出】数据汇总!$1:$1,0))/100,"") -> 172.75038 | ... BL40: =IFERROR(INDEX(【输出】数据汇总!$A:$AZ,MATCH(横向对比!BL$4&横向对比!$B40,【输出】数据汇总!$A:$A,0),MATCH(横向对比!$B$36,【输出】数据汇总!$1:$1,0))/100,"") -> 73.755638
A41: ⑤ | B41: 关注类贷款余额 | C41: =IFERROR(INDEX(【输出】数据汇总!$A:$AZ,MATCH(横向对比!C$4&横向对比!$B41,【输出】数据汇总!$A:$A,0),MATCH(横向对比!$B$36,【输出】数据汇总!$1:$1,0))/100,"") -> 30849.717 | D41: =IFERROR(INDEX(【输出】数据汇总!$A:$AZ,MATCH(横向对比!D$4&横向对比!$B41,【输出】数据汇总!$A:$A,0),MATCH(横向对比!$B$36,【输出】数据汇总!$1:$1,0))/100,"") -> 20329.15 | E41: =IFERROR(INDEX(【输出】数据汇总!$A:$AZ,MATCH(横向对比!E$4&横向对比!$B41,【输出】数据汇总!$A:$A,0),MATCH(横向对比!$B$36,【输出】数据汇总!$1:$1,0))/100,"") -> 7799.83 | F41: =IFERROR(INDEX(【输出】数据汇总!$A:$AZ,MATCH(横向对比!F$4&横向对比!$B41,【输出】数据汇总!$A:$A,0),MATCH(横向对比!$B$36,【输出】数据汇总!$1:$1,0))/100,"") -> 2183.87 | G41: =IFERROR(INDEX(【输出】数据汇总!$A:$AZ,MATCH(横向对比!G$4&横向对比!$B41,【输出】数据汇总!$A:$A,0),MATCH(横向对比!$B$36,【输出】数据汇总!$1:$1,0))/100,"") -> 536.86737 | H41: =IFERROR(INDEX(【输出】数据汇总!$A:$AZ,MATCH(横向对比!H$4&横向对比!$B41,【输出】数据汇总!$A:$A,0),MATCH(横向对比!$B$36,【输出】数据汇总!$1:$1,0))/100,"") | I41: =IFERROR(INDEX(【输出】数据汇总!$A:$AZ,MATCH(横向对比!I$4&横向对比!$B41,【输出】数据汇总!$A:$A,0),MATCH(横向对比!$B$36,【输出】数据汇总!$1:$1,0))/100,"") -> 2140.4217 | J41: =IFERROR(INDEX(【输出】数据汇总!$A:$AZ,MATCH(横向对比!J$4&横向对比!$B41,【输出】数据汇总!$A:$A,0),MATCH(横向对比!$B$36,【输出】数据汇总!$1:$1,0))/100,"") -> 5758.83 | ... AA41: =IFERROR(INDEX(【输出】数据汇总!$A:$AZ,MATCH(横向对比!AA$4&横向对比!$B41,【输出】数据汇总!$A:$A,0),MATCH(横向对比!$B$36,【输出】数据汇总!$1:$1,0))/100,"") -> 292.86155 | AB41: =IFERROR(INDEX(【输出】数据汇总!$A:$AZ,MATCH(横向对比!AB$36&横向对比!$B41,【输出】数据汇总!$A:$A,0),MATCH(横向对比!$B$36,【输出】数据汇总!$1:$1,0))/100,"") -> 171.02 | AC41: =IFERROR(INDEX(【输出】数据汇总!$A:$AZ,MATCH(横向对比!AC$4&横向对比!$B41,【输出】数据汇总!$A:$A,0),MATCH(横向对比!$B$36,【输出】数据汇总!$1:$1,0))/100,"") -> 146.57639 | AD41: =IFERROR(INDEX(【输出】数据汇总!$A:$AZ,MATCH(横向对比!AD$4&横向对比!$B41,【输出】数据汇总!$A:$A,0),MATCH(横向对比!$B$36,【输出】数据汇总!$1:$1,0))/100,"") -> 51.72787 | AE41: =IFERROR(INDEX(【输出】数据汇总!$A:$AZ,MATCH(横向对比!AE$4&横向对比!$B41,【输出】数据汇总!$A:$A,0),MATCH(横向对比!$B$36,【输出】数据汇总!$1:$1,0))/100,"") -> 36.68327 | AF41: =IFERROR(INDEX(【输出】数据汇总!$A:$AZ,MATCH(横向对比!AF$4&横向对比!$B41,【输出】数据汇总!$A:$A,0),MATCH(横向对比!$B$36,【输出】数据汇总!$1:$1,0))/100,"") -> 199.70884 | AG41: =IFERROR(INDEX(【输出】数据汇总!$A:$AZ,MATCH(横向对比!AG$4&横向对比!$B41,【输出】数据汇总!$A:$A,0),MATCH(横向对比!$B$36,【输出】数据汇总!$1:$1,0))/100,"") -> 102.1187 | AH41: =IFERROR(INDEX(【输出】数据汇总!$A:$AZ,MATCH(横向对比!AH$4&横向对比!$B41,【输出】数据汇总!$A:$A,0),MATCH(横向对比!$B$36,【输出】数据汇总!$1:$1,0))/100,"") -> 107.23273 | AI41: =IFERROR(INDEX(【输出】数据汇总!$A:$AZ,MATCH(横向对比!AI$4&横向对比!$B41,【输出】数据汇总!$A:$A,0),MATCH(横向对比!$B$36,【输出】数据汇总!$1:$1,0))/100,"") -> 82.28182 | AJ41: =IFERROR(INDEX(【输出】数据汇总!$A:$AZ,MATCH(横向对比!AJ$4&横向对比!$B41,【输出】数据汇总!$A:$A,0),MATCH(横向对比!$B$36,【输出】数据汇总!$1:$1,0))/100,"") -> 27.41534 | ... BA41: =IFERROR(INDEX(【输出】数据汇总!$A:$AZ,MATCH(横向对比!BA$4&横向对比!$B41,【输出】数据汇总!$A:$A,0),MATCH(横向对比!$B$36,【输出】数据汇总!$1:$1,0))/100,"") -> 492.9212 | BB41: =IFERROR(INDEX(【输出】数据汇总!$A:$AZ,MATCH(横向对比!BB$36&横向对比!$B41,【输出】数据汇总!$A:$A,0),MATCH(横向对比!$B$36,【输出】数据汇总!$1:$1,0))/100,"") -> 162.203 | BC41: =IFERROR(INDEX(【输出】数据汇总!$A:$AZ,MATCH(横向对比!BC$4&横向对比!$B41,【输出】数据汇总!$A:$A,0),MATCH(横向对比!$B$36,【输出】数据汇总!$1:$1,0))/100,"") -> 136.4697 | BD41: =IFERROR(INDEX(【输出】数据汇总!$A:$AZ,MATCH(横向对比!BD$4&横向对比!$B41,【输出】数据汇总!$A:$A,0),MATCH(横向对比!$B$36,【输出】数据汇总!$1:$1,0))/100,"") -> 18.45647 | BE41: =IFERROR(INDEX(【输出】数据汇总!$A:$AZ,MATCH(横向对比!BE$4&横向对比!$B41,【输出】数据汇总!$A:$A,0),MATCH(横向对比!$B$36,【输出】数据汇总!$1:$1,0))/100,"") -> 110.189 | BF41: =IFERROR(INDEX(【输出】数据汇总!$A:$AZ,MATCH(横向对比!BF$4&横向对比!$B41,【输出】数据汇总!$A:$A,0),MATCH(横向对比!$B$36,【输出】数据汇总!$1:$1,0))/100,"") -> 94.641 | BG41: =IFERROR(INDEX(【输出】数据汇总!$A:$AZ,MATCH(横向对比!BG$4&横向对比!$B41,【输出】数据汇总!$A:$A,0),MATCH(横向对比!$B$36,【输出】数据汇总!$1:$1,0))/100,"") -> 125.5 | BH41: =IFERROR(INDEX(【输出】数据汇总!$A:$AZ,MATCH(横向对比!BH$4&横向对比!$B41,【输出】数据汇总!$A:$A,0),MATCH(横向对比!$B$36,【输出】数据汇总!$1:$1,0))/100,"") -> 237.997 | BI41: =IFERROR(INDEX(【输出】数据汇总!$A:$AZ,MATCH(横向对比!BI$4&横向对比!$B41,【输出】数据汇总!$A:$A,0),MATCH(横向对比!$B$36,【输出】数据汇总!$1:$1,0))/100,"") -> 108.5416 | BJ41: =IFERROR(INDEX(【输出】数据汇总!$A:$AZ,MATCH(横向对比!BJ$4&横向对比!$B41,【输出】数据汇总!$A:$A,0),MATCH(横向对比!$B$36,【输出】数据汇总!$1:$1,0))/100,"") -> 277.65042 | ... BL41: =IFERROR(INDEX(【输出】数据汇总!$A:$AZ,MATCH(横向对比!BL$4&横向对比!$B41,【输出】数据汇总!$A:$A,0),MATCH(横向对比!$B$36,【输出】数据汇总!$1:$1,0))/100,"") -> 74.99926
A42: ⑥=MAX(②+③，④+⑤) | B42: 广义风险贷款 | C42: =MAX(C38+C39,C40+C41) -> 53514.05 | D42: =MAX(D38+D39,D40+D41) -> 36256.5 | E42: =MAX(E38+E39,E40+E41) -> 12677.03 | F42: =MAX(F38+F39,F40+F41) -> 3724.8943 | G42: =MAX(G38+G39,G40+G41) -> 855.62571 | H42: =MAX(H38+H39,H40+H41) -> #VALUE! | I42: =MAX(I38+I39,I40+I41) -> 3248.2387 | J42: =IFERROR(INDEX(【输出】数据汇总!$A:$AZ,MATCH(横向对比!J$4&横向对比!$B42,【输出】数据汇总!$A:$A,0),MATCH(横向对比!$B$36,【输出】数据汇总!$1:$1,0))/100,"") -> 9773.5226 | K42: =IFERROR(INDEX(【输出】数据汇总!$A:$AZ,MATCH(横向对比!K$4&横向对比!$B42,【输出】数据汇总!$A:$A,0),MATCH(横向对比!$B$36,【输出】数据汇总!$1:$1,0))/100,"") -> 8617.2561 | L42: =IFERROR(INDEX(【输出】数据汇总!$A:$AZ,MATCH(横向对比!L$4&横向对比!$B42,【输出】数据汇总!$A:$A,0),MATCH(横向对比!$B$36,【输出】数据汇总!$1:$1,0))/100,"") -> 7132.3695 | M42: =IFERROR(INDEX(【输出】数据汇总!$A:$AZ,MATCH(横向对比!M$4&横向对比!$B42,【输出】数据汇总!$A:$A,0),MATCH(横向对比!$B$36,【输出】数据汇总!$1:$1,0))/100,"") -> 6157.7619 | N42: =IFERROR(INDEX(【输出】数据汇总!$A:$AZ,MATCH(横向对比!N$4&横向对比!$B42,【输出】数据汇总!$A:$A,0),MATCH(横向对比!$B$36,【输出】数据汇总!$1:$1,0))/100,"") -> 2026.8189 | O42: =IFERROR(INDEX(【输出】数据汇总!$A:$AZ,MATCH(横向对比!O$4&横向对比!$B42,【输出】数据汇总!$A:$A,0),MATCH(横向对比!$B$36,【输出】数据汇总!$1:$1,0))/100,"") -> 2582.7779 | P42: =IFERROR(INDEX(【输出】数据汇总!$A:$AZ,MATCH(横向对比!P$4&横向对比!$B42,【输出】数据汇总!$A:$A,0),MATCH(横向对比!$B$36,【输出】数据汇总!$1:$1,0))/100,"") -> 1676.5153 | Q42: =IFERROR(INDEX(【输出】数据汇总!$A:$AZ,MATCH(横向对比!Q$4&横向对比!$B42,【输出】数据汇总!$A:$A,0),MATCH(横向对比!$B$36,【输出】数据汇总!$1:$1,0))/100,"") -> 1617.4408 | ... AA42: =IFERROR(INDEX(【输出】数据汇总!$A:$AZ,MATCH(横向对比!AA$4&横向对比!$B42,【输出】数据汇总!$A:$A,0),MATCH(横向对比!$B$36,【输出】数据汇总!$1:$1,0))/100,"") -> 462.42563 | AB42: =IFERROR(INDEX(【输出】数据汇总!$A:$AZ,MATCH(横向对比!AB$36&横向对比!$B42,【输出】数据汇总!$A:$A,0),MATCH(横向对比!$B$36,【输出】数据汇总!$1:$1,0))/100,"") -> 298.18419 | AC42: =IFERROR(INDEX(【输出】数据汇总!$A:$AZ,MATCH(横向对比!AC$4&横向对比!$B42,【输出】数据汇总!$A:$A,0),MATCH(横向对比!$B$36,【输出】数据汇总!$1:$1,0))/100,"") -> 263.09896 | AD42: =IFERROR(INDEX(【输出】数据汇总!$A:$AZ,MATCH(横向对比!AD$4&横向对比!$B42,【输出】数据汇总!$A:$A,0),MATCH(横向对比!$B$36,【输出】数据汇总!$1:$1,0))/100,"") -> 128.44365 | AE42: =IFERROR(INDEX(【输出】数据汇总!$A:$AZ,MATCH(横向对比!AE$4&横向对比!$B42,【输出】数据汇总!$A:$A,0),MATCH(横向对比!$B$36,【输出】数据汇总!$1:$1,0))/100,"") -> 91.688671 | AF42: =IFERROR(INDEX(【输出】数据汇总!$A:$AZ,MATCH(横向对比!AF$4&横向对比!$B42,【输出】数据汇总!$A:$A,0),MATCH(横向对比!$B$36,【输出】数据汇总!$1:$1,0))/100,"") -> 270.22376 | AG42: =IFERROR(INDEX(【输出】数据汇总!$A:$AZ,MATCH(横向对比!AG$4&横向对比!$B42,【输出】数据汇总!$A:$A,0),MATCH(横向对比!$B$36,【输出】数据汇总!$1:$1,0))/100,"") -> 160.46017 | AH42: =IFERROR(INDEX(【输出】数据汇总!$A:$AZ,MATCH(横向对比!AH$4&横向对比!$B42,【输出】数据汇总!$A:$A,0),MATCH(横向对比!$B$36,【输出】数据汇总!$1:$1,0))/100,"") -> 165.62111 | AI42: =IFERROR(INDEX(【输出】数据汇总!$A:$AZ,MATCH(横向对比!AI$4&横向对比!$B42,【输出】数据汇总!$A:$A,0),MATCH(横向对比!$B$36,【输出】数据汇总!$1:$1,0))/100,"") -> 153.75445 | AJ42: =IFERROR(INDEX(【输出】数据汇总!$A:$AZ,MATCH(横向对比!AJ$4&横向对比!$B42,【输出】数据汇总!$A:$A,0),MATCH(横向对比!$B$36,【输出】数据汇总!$1:$1,0))/100,"") -> 57.585603 | ... BA42: =IFERROR(INDEX(【输出】数据汇总!$A:$AZ,MATCH(横向对比!BA$4&横向对比!$B42,【输出】数据汇总!$A:$A,0),MATCH(横向对比!$B$36,【输出】数据汇总!$1:$1,0))/100,"") -> 847.74051 | BB42: =IFERROR(INDEX(【输出】数据汇总!$A:$AZ,MATCH(横向对比!BB$36&横向对比!$B42,【输出】数据汇总!$A:$A,0),MATCH(横向对比!$B$36,【输出】数据汇总!$1:$1,0))/100,"") -> 243.67779 | BC42: =IFERROR(INDEX(【输出】数据汇总!$A:$AZ,MATCH(横向对比!BC$4&横向对比!$B42,【输出】数据汇总!$A:$A,0),MATCH(横向对比!$B$36,【输出】数据汇总!$1:$1,0))/100,"") -> 222.58683 | BD42: =IFERROR(INDEX(【输出】数据汇总!$A:$AZ,MATCH(横向对比!BD$4&横向对比!$B42,【输出】数据汇总!$A:$A,0),MATCH(横向对比!$B$36,【输出】数据汇总!$1:$1,0))/100,"") -> 32.24235 | BE42: =IFERROR(INDEX(【输出】数据汇总!$A:$AZ,MATCH(横向对比!BE$4&横向对比!$B42,【输出】数据汇总!$A:$A,0),MATCH(横向对比!$B$36,【输出】数据汇总!$1:$1,0))/100,"") -> 153.63237 | BF42: =IFERROR(INDEX(【输出】数据汇总!$A:$AZ,MATCH(横向对比!BF$4&横向对比!$B42,【输出】数据汇总!$A:$A,0),MATCH(横向对比!$B$36,【输出】数据汇总!$1:$1,0))/100,"") -> 131.56998 | BG42: =IFERROR(INDEX(【输出】数据汇总!$A:$AZ,MATCH(横向对比!BG$4&横向对比!$B42,【输出】数据汇总!$A:$A,0),MATCH(横向对比!$B$36,【输出】数据汇总!$1:$1,0))/100,"") -> 233.35223 | BH42: =IFERROR(INDEX(【输出】数据汇总!$A:$AZ,MATCH(横向对比!BH$4&横向对比!$B42,【输出】数据汇总!$A:$A,0),MATCH(横向对比!$B$36,【输出】数据汇总!$1:$1,0))/100,"") -> 794.39793 | BI42: =IFERROR(INDEX(【输出】数据汇总!$A:$AZ,MATCH(横向对比!BI$4&横向对比!$B42,【输出】数据汇总!$A:$A,0),MATCH(横向对比!$B$36,【输出】数据汇总!$1:$1,0))/100,"") -> 170.11625 | BJ42: =IFERROR(INDEX(【输出】数据汇总!$A:$AZ,MATCH(横向对比!BJ$4&横向对比!$B42,【输出】数据汇总!$A:$A,0),MATCH(横向对比!$B$36,【输出】数据汇总!$1:$1,0))/100,"") -> 450.4008 | ... BL42: =IFERROR(INDEX(【输出】数据汇总!$A:$AZ,MATCH(横向对比!BL$4&横向对比!$B42,【输出】数据汇总!$A:$A,0),MATCH(横向对比!$B$36,【输出】数据汇总!$1:$1,0))/100,"") -> 148.7549
...

Sheet 纵向时序
A1: 可选标签 | D1: 亿元
